Workbook
Name _?: #REF!
Name _??????: #REF!
Name __abb91: [1]chitimc!#REF!
Name __CT250: '[1]dongia (2)'!#REF!
Name __ddn400: #REF!
Name __ddn600: #REF!
Name __dgt100: '[1]dongia (2)'!#REF!
Name __MAC12: #REF!
Name __MAC46: #REF!
Name __NCL100: #REF!
Name __NCL200: #REF!
Name __NCL250: #REF!
Name __nin190: [2]VC!#REF!
Name __sc1: #REF!
Name __SC2: #REF!
Name __sc3: [2]VC!#REF!
Name __SN3: #REF!
Name __th100: '[1]dongia (2)'!#REF!
Name __TH160: '[1]dongia (2)'!#REF!
Name __TL1: #REF!
Name __TL2: #REF!
Name __TL3: #REF!
Name __TLA120: #REF!
Name __TLA35: #REF!
Name __TLA50: #REF!
Name __TLA70: #REF!
Name __TLA95: #REF!
Name __TR250: '[1]dongia (2)'!#REF!
Name __tr375: [1]giathanh1!#REF!
Name __VL100: #REF!
Name __VL200: #REF!
Name _1_?: #REF!
Name _2_??????: #REF!
Name _abb91: [1]chitimc!#REF!
Name _CT250: '[1]dongia (2)'!#REF!
Name _ddn400: #REF!
Name _ddn600: #REF!
Name _dgt100: '[1]dongia (2)'!#REF!
Name _MAC12: #REF!
Name _MAC46: #REF!
Name _NCL100: #REF!
Name _NCL200: #REF!
Name _NCL250: #REF!
Name _nin190: [3]VC!#REF!
Name _sc1: #REF!
Name _SC2: #REF!
Name _sc3: [3]VC!#REF!
Name _SN3: #REF!
Name _th100: '[1]dongia (2)'!#REF!
Name _TH160: '[1]dongia (2)'!#REF!
Name _TL1: #REF!
Name _TL2: #REF!
Name _TL3: #REF!
Name _TLA120: #REF!
Name _TLA35: #REF!
Name _TLA50: #REF!
Name _TLA70: #REF!
Name _TLA95: #REF!
Name _TR250: '[1]dongia (2)'!#REF!
Name _tr375: [1]giathanh1!#REF!

Sheet BGCTLOVAD
B1: THÔNG TIN KHÁCH HÀNG | G1: THƯ BÁO GIÁ
C2: Kính gửi: | D2: Ban quản lý dự án Sunrise Riverside Lô E
C3: Công ty: | G3: Ngày báo giá: | H3: =TODAY() -> 46195
C4: Điện thoại: | G4: Giá trị đến: | H4: =H3+30 -> 46225
C5: Thông tin dự án: | D5: Xã Phước Kiển, Huyện Nhà Bè, Tp. Hồ Chí Minh | G5: Nhân viên:
C7: Cám ơn Quý khách hàng đã quan tâm đến sản phẩm của công ty chúng tôi, theo yêu cầu của Quý khách chúng tôi trân trọng trình bảng báo giá như sau:
B8: STT | C8: TÊN HÀNG/MÔ TẢ | E8: ĐVT | F8: SL | G8: ĐƠN GIÁ | H8: THÀNH TIỀN | I8: GHI CHÚ
B9: I. THIẾT BỊ PHẦN CỨNG | H9: =SUBTOTAL(9,H10:H32) -> 434818000
B10: 1 | C10: =bgct!$C10 -> Camera IP Dome 2MP - Cảm biến ảnh: CMOS 1/2.9″ 2.0megapixel - Chuẩn nén H.265+/ H.265/ H.264+/ H.264 - Độ phân giải 1920×1080 - Tính năng lọc hồng ngoại ICR, 0lux với hồng ngoại - Ống kính 2.8mm - Công suất : 6.5W | E10: =VLOOKUP(C10,bgct!$C$10:$E$17,2,0) -> Cái | F10: =VLOOKUP(C10,bgct!$C$10:$E$17,3,0) -> 113 | G10: 730000 | H10: =G10*F10 -> 82490000
B11: 2 | C11: =bgct!$C11 -> Camera IP thân 2MP '- Cảm biến ảnh: CMOS 1/2.9″ 2.0megapixel - Chuẩn nén H.265+/ H.265/ H.264+/ H.264 - Độ phân giải 1920×1080 - Tính năng lọc hồng ngoại ICR, 0lux với hồng ngoại - Ống kính 2.8mm - Công suất : 6.5W | E11: =VLOOKUP(C11,bgct!$C$10:$E$17,2,0) -> Cái | F11: =VLOOKUP(C11,bgct!$C$10:$E$17,3,0) -> 14 | G11: 710000 | H11: =G11*F11 -> 9940000
B12: 3 | C12: =bgct!$C12 -> Đầu ghi hình camera IP 32 kênh '– Chuẩn nén H.265+/H.265/H.264+/H.264 – Hỗ trợ độ phân giải ghi hình lên đến 12MP – Băng thông đầu vào 256Mbps – Băng thông đầu ra 160Mbps – Hỗ trợ 4 ổ cứng, dung lượng tối đa mỗi ổ 10TB - Công suất 20W | E12: =VLOOKUP(C12,bgct!$C$10:$E$17,2,0) -> Cái | F12: =VLOOKUP(C12,bgct!$C$10:$E$17,3,0) -> 4 | G12: 9340000 | H12: =G12*F12 -> 37360000
B13: 4 | C13: =bgct!$C13 -> - Ổ cứng 8TB HDD chuyên nghiệp cho camera. - Dung lượng: 8TB - Kết nối: SATA III - Cache: 256MB - Công suất : 5.3W | E13: =VLOOKUP(C13,bgct!$C$10:$E$17,2,0) -> Cái | F13: =VLOOKUP(C13,bgct!$C$10:$E$17,3,0) -> 8 | G13: 5992000 | H13: =G13*F13 -> 47936000
B14: 5 | C14: =bgct!$C14 -> Swtich POE 24 cổng - Hỗ trợ 24 × 100Mbps PoE RJ45 ports, 2 × gigabit combos. - Cổng ưu tiên: Cổng 1 - 8. - Bảng địa chỉ MAC: 16K. - Khả năng chuyển mạch 8.8Gbps. - Tốc độ chuyển tiếp gói tin: 6.5472Mpps. - Tương thích chuẩn IEEE 802.3af/at. - Công suất PoE: 370W. | E14: Cái | F14: 4 | G14: 5077000 | H14: =G14*F14 -> 20308000
B15: 6 | C15: =bgct!$C15 -> - Switch mạng thông minh 16 cổng PoE. - Hỗ trợ tính năng cấu hình quản lý bằng phần mềm. -16 cổng PoE RJ45 100Mbps, 2 cổng RJ45 Gigabit, 2 cổng quang -Tự tương thích chuẩn IEEE 802.3af/at. - Công suất PoE 230W. | E15: Cái | F15: 4 | G15: 4438000 | H15: =G15*F15 -> 17752000
B16: 7 | C16: =bgct!$C16 -> Switch 16 port - Hỗ trợ 16 cổng Gigabit Ethernet RJ-45 - Công suất : 9.96W | E16: Cái | F16: 1 | G16: 3892000 | H16: =G16*F16 -> 3892000
B17: 8 | C17: =bgct!$B18 -> Màn hình quan sát SamSung 43inch | E17: Bộ | F17: =bgct!$E$18 -> 4 | G17: 9000000 | H17: =G17*F17 -> 36000000
B18: 9 | C18: =bgct!$B19 -> Khung kệ tivi | E18: Cái | F18: =bgct!$E$18 -> 4 | G18: 500000 | H18: =G18*F18 -> 2000000
B19: 10 | C19: =bgct!$B20 -> Cáp HDMI 15m Unitek | E19: Sợi | F19: =bgct!$E$18 -> 4 | G19: 700000 | H19: =G19*F19 -> 2800000
B20: 11 | C20: =bgct!$B22 -> Cáp quang 4FO | E20: Mét | F20: 400 | G20: 6000 | H20: =G20*F20 -> 2400000
B21: 12 | C21: =bgct!$B23 -> Cáp mạng Cat5E | E21: Mét | F21: 7300 | G21: 10500 | H21: =G21*F21 -> 76650000
B22: 13 | C22: =bgct!$B24 -> Converter A/B 1000M | E22: Bộ | F22: 4 | G22: 1380000 | H22: =G22*F22 -> 5520000
B23: 14 | C23: =bgct!$B25 -> Tủ mạng rack 6U | E23: Cái | F23: 2 | G23: 1250000 | H23: =G23*F23 -> 2500000
B24: 15 | C24: =bgct!$B26 -> Tủ mạng rack 10U | E24: Cái | F24: 2 | G24: 1760000 | H24: =G24*F24 -> 3520000
B25: 16 | C25: =bgct!$B27 -> Tủ mạng rack 42U | E25: Cái | F25: 1 | G25: 8820000 | H25: =G25*F25 -> 8820000
B26: 17 | C26: =bgct!$B28 -> ODF 12 FO | E26: Cái | F26: 1 | G26: 750000 | H26: =G26*F26 -> 750000
B27: 18 | C27: =bgct!$B30 -> Dây điện CVV 2x2.5 | E27: =VLOOKUP(C27,'PTLL (2)'!$B$5:$J$42,2,0) -> Mét | F27: 200 | G27: 23000 | H27: =G27*F27 -> 4600000
B28: 19 | C28: =bgct!$B31 -> Thanh nguồn PDU đa năng 6 ổ cắm 3 chấu chuẩn 19" | E28: =VLOOKUP(C28,'PTLL (2)'!$B$5:$J$42,2,0) -> Cái | F28: =VLOOKUP(C28,'PTLL (2)'!$B$5:$J$42,3,0) -> 3 | G28: 1080000 | H28: =G28*F28 -> 3240000
B29: 20 | C29: =bgct!$B33 -> Nguồn lưu điện 2KVA UPS | E29: =VLOOKUP(C29,'PTLL (2)'!$B$5:$J$42,2,0) -> Bộ | F29: =VLOOKUP(C29,'PTLL (2)'!$B$5:$J$42,3,0) -> 2 | G29: 6980000 | H29: =G29*F29 -> 13960000
B30: 21 | C30: =bgct!$B34 -> Nguồn lưu điện 1K2VA UPS | E30: =VLOOKUP(C30,'PTLL (2)'!$B$5:$J$42,2,0) -> Bộ | F30: =VLOOKUP(C30,'PTLL (2)'!$B$5:$J$42,3,0) -> 2 | G30: 3020000 | H30: =G30*F30 -> 6040000
B31: 22 | C31: =bgct!$B35 -> Nguồn lưu điện 3KVA UPS | E31: =VLOOKUP(C31,'PTLL (2)'!$B$5:$J$42,2,0) -> Bộ | F31: =VLOOKUP(C31,'PTLL (2)'!$B$5:$J$42,3,0) -> 1 | G31: 9640000 | H31: =G31*F31 -> 9640000
B32: 23 | C32: =bgct!$B$37 -> Vật tư phụ | E32: Gói | F32: 1 | G32: 36700000 | H32: =G32*F32 -> 36700000
B33: II. CHI PHÍ LẮP ĐẶT | H33: =SUBTOTAL(9,H34) -> 112000000
B34: 1 | C34: Chi phí lắp đặt | E34: Gói | F34: 1 | G34: 112000000 | H34: =G34*F34 -> 112000000
B35: CỘNG CHƯA VAT (VNĐ): | H35: =SUBTOTAL(9,H8:H34) -> 546818000
B36: 10% VAT (VNĐ): | H36: =H35*0.1 -> 54681800
B37: TỔNG CỘNG BAO GỒM VAT (VNĐ): | H37: =H35+H36 -> 601499800
B38: Bằng chữ: | E38: =[14]!vnd(H37) -> #NAME?
C40: Điều khoản thương mại:
C41: -Tạm ứng 50%, 50% còn lại thanh toán ngay sau khi giao hàng - Hình thức thanh toán bằng chuyển khoản.
C42: - Sản phẩm, hàng hóa do bên công ty Lovad cung cấp tại thị trường Việt Nam có nguồn gốc và xuất xứ rõ ràng, mới 100%, nguyên đai, nguyên kiện, đảm bảo đúng theo tiêu chuẩn của nhà sản xuất. - Sản phẩm, hàng hóa được bảo hành 12 tháng. - Sản phẩm, hàng hóa được bảo hành khi xảy ra những lỗi kỹ thuật do nhà sản xuất. Các yếu tố ngoại quan như trường hợp do sét đánh, sử dụng điện áp sai quy định, cháy nổ IC, có dấu hiệu rơi vỡ...vv, Lovad sẽ không thực hiện chế độ bảo hành sản phẩm như trên. - Phần mềm chỉ được cấp lại license miễn phí khi thỏa một trong các điều kiện sau: 1) Đổi máy tính mới khi máy tính cũ vẫn còn hoạt động bình thường; 2) Thay đổi linh kiện máy tính phải giữ lại ít nhất 1 trong các linh kiện sau: ổ cứng, mainboard, chipset CPU; 3) Dùng dịch vụ bảo trì hàng năm do LOVAD cung cấp. - Nâng cấp từ phần mềm bản thấp lên bản cao, tính phí 65% license bản cao hơn.
...

Sheet PTLL (3)
A1: PHÂN TÍCH LÃI LỖ HỆ THỐNG 132 CAMERA SUNRISE CITY LÔ E | S1: Giá trị phải phân bổ | T1: =C71 -> 98696329 | X1: ĐÃ PHÂN BỔ | Y1: =AC44-U44 -> #DIV/0!
A2: STT | B2: NỘI DUNG CÔNG VIỆC | C2: Đ.VỊ | D2: SLG | E2: GIÁ NHẬP | H2: GIÁ BÁN | K2: LỢI NHUẬN | L2: GHI CHÚ | M2: GIÁ NIÊM YẾT | N2: % GIẢM | O2: Giá bán ra | P2: % lãi | S2: Giá trị được chọn pb | T2: =SUMIF($AD$5:$AD$27,C72,$U$5:$U$27) -> 0 | U2: =T1/T2 -> #DIV/0! | X2: Giá trị còn lại phải pb | Y2: =T1-Y1 -> #DIV/0!
E3: G.Đơn vị | F3: Thành tiền | G3: VNĐ | H3: % | I3: G.Đơn vị | J3: Thành tiền | P3: giá bán/giá nhập | R3: SL | S3: Giá ncc | T3: Giá báo | U3: Thành tiền | V3: Giá sau PB LẦN 1 | W3: %tăng so với giá trị báo | X3: Giá sau PB LẦN 2 | Y3: %tăng so với giá trị báo | Z3: SL PB | AA3: SL CUỐI | AB3: ĐƠN GIÁ | AC3: THÀNH TIỀN | AD3: Mã Pb
A4: I | B4: HỆ THỐNG CAMERA | F4: =SUBTOTAL(9,F5:F14) -> 197734000 | H4: =K4/F4 -> 0.35699475 | J4: =SUBTOTAL(9,J5:J14) -> 268324000 | K4: =SUBTOTAL(9,K5:K14) -> 70590000
A5: =_xlfn.AGGREGATE(3,5,$B$5:B5) -> 1 | B5: Camera IP Dome 2MP HIKVISION DS-2CD1121G0-I | C5: Cái | D5: =113+5 -> 118 | E5: 538000 | F5: =E5*D5 -> 63484000 | H5: 0.46 | I5: =ROUNDUP((E5+G5+E5*H5),-3) -> 786000 | J5: =I5*D5 -> 92748000 | K5: =J5-F5 -> 29264000 | M5: =1300000/1.1 -> 1181818.2 | N5: 0.45 | O5: =M5*(1-N5) -> 650000 | P5: =O5/E5 -> 1.2081784 | Q5: =E5/M5 -> 0.45523077 | R5: =D5 -> 118 | S5: =E5 -> 538000 | T5: =I5 -> 786000 | U5: =T5*R5 -> 92748000 | V5: =IF(AD5=1,U5*$U$2/R5+T5,T5) -> #DIV/0! | W5: =1-T5/V5 -> #DIV/0! | X5: 940000 | Y5: =IF(X5<>0,1-T5/X5," ") -> 0.16382979 | AA5: =IF(Z5<>0,Z5,R5) -> 118 | AB5: =IF(X5<>0, X5,V5) -> 940000 | AC5: =AA5*AB5 -> 110920000 | AD5: 1
A6: =_xlfn.AGGREGATE(3,5,$B$5:B6) -> 2 | B6: Camera IP thân 2MP HIKVISION DS-2CD1021G0-I | C6: Cái | D6: 14 | E6: 510000 | F6: =E6*D6 -> 7140000 | H6: 0.46 | I6: =ROUNDUP((E6+G6+E6*H6),-3) -> 745000 | J6: =I6*D6 -> 10430000 | K6: =J6-F6 -> 3290000 | M6: =1300000/1.1 -> 1181818.2 | N6: 0.465 | O6: =M6*(1-N6) -> 632272.73 | P6: =O6/E6 -> 1.2397504
A7: =_xlfn.AGGREGATE(3,5,$B$5:B7) -> 3 | B7: Đầu ghi hình camera IP 32 kênh HIKVISION DS-7732NXI-K4 | C7: Cái | D7: 4 | E7: 6650000 | F7: =E7*D7 -> 26600000 | H7: 0.45 | I7: =ROUNDUP((E7+G7+E7*H7),-3) -> 9643000 | J7: =I7*D7 -> 38572000 | K7: =J7-F7 -> 11972000 | M7: =16690000/1.1 -> 15172727 | N7: 0.43 | O7: =M7*(1-N7) -> 8648454.5 | P7: =O7/E7 -> 1.3005195 | R7: =D7 -> 4 | S7: =E7 -> 6650000 | T7: =I7 -> 9643000 | U7: =T7*R7 -> 38572000 | V7: =IF(AD7=1,U7*$U$2/R7+T7,T7) -> #DIV/0! | W7: =1-T7/V7 -> #DIV/0! | X7: 66800000 | Y7: =IF(X7<>0,1-T7/X7," ") -> 0.85564371 | AA7: =IF(Z7<>0,Z7,R7) -> 4 | AB7: =IF(X7<>0, X7,V7) -> 66800000 | AC7: =AA7*AB7 -> 267200000 | AD7: 1
A8: =_xlfn.AGGREGATE(3,5,$B$5:B8) -> 4 | B8: Ổ Cứng 8T WESTERN | C8: Cái | D8: 8 | E8: 4930000 | F8: =E8*D8 -> 39440000 | H8: 0.22 | I8: =ROUNDUP((E8+G8+E8*H8),-3) -> 6015000 | J8: =I8*D8 -> 48120000 | K8: =J8-F8 -> 8680000 | M8: 5879000 | N8: 0.18 | O8: =M8*(1-N8) -> 4820780 | P8: =O8/E8 -> 0.97784584 | R8: =D8 -> 8 | S8: =E8 -> 4930000 | T8: =I8 -> 6015000 | U8: =T8*R8 -> 48120000 | V8: =IF(AD8=1,U8*$U$2/R8+T8,T8) -> 6015000 | W8: =1-T8/V8 -> 0 | Y8: =IF(X8<>0,1-T8/X8," ") | AA8: =IF(Z8<>0,Z8,R8) -> 8 | AB8: =IF(X8<>0, X8,V8) -> 6015000 | AC8: =AA8*AB8 -> 48120000
A9: =_xlfn.AGGREGATE(3,5,$B$5:B9) -> 5 | B9: Switch Hikvision POE 24 cổng DS-3E1326P-EI | C9: Cái | D9: 4 | E9: 3660000 | F9: =E9*D9 -> 14640000 | H9: 0.4 | I9: =ROUNDUP((E9+G9+E9*H9),-3) -> 5124000 | J9: =I9*D9 -> 20496000 | K9: =J9-F9 -> 5856000 | M9: =8730000/1.1 -> 7936363.6 | N9: 0.43 | O9: =M9*(1-N9) -> 4523727.3 | P9: =O9/E9 -> 1.2359911 | R9: =D9 -> 4 | S9: =E9 -> 3660000 | T9: =I9 -> 5124000 | U9: =T9*R9 -> 20496000 | V9: =IF(AD9=1,U9*$U$2/R9+T9,T9) -> #DIV/0! | W9: =1-T9/V9 -> #DIV/0! | X9: 8480000 | Y9: =IF(X9<>0,1-T9/X9," ") -> 0.39575472 | AA9: =IF(Z9<>0,Z9,R9) -> 4 | AB9: =IF(X9<>0, X9,V9) -> 8480000 | AC9: =AA9*AB9 -> 33920000 | AD9: 1
A10: =_xlfn.AGGREGATE(3,5,$B$5:B10) -> 6 | B10: Switch Hikvision POE 16 cổng DS-3E1318P-EI | C10: Cái | D10: 4 | E10: 2920000 | F10: =E10*D10 -> 11680000 | H10: 0.4 | I10: =ROUNDUP((E10+G10+E10*H10),-3) -> 4088000 | J10: =I10*D10 -> 16352000 | K10: =J10-F10 -> 4672000 | M10: 6950000 | N10: 0.43 | O10: =M10*(1-N10) -> 3961500 | P10: =O10/E10 -> 1.3566781 | R10: =D10 -> 4 | S10: =E10 -> 2920000 | T10: =I10 -> 4088000 | U10: =T10*R10 -> 16352000 | V10: =IF(AD10=1,U10*$U$2/R10+T10,T10) -> #DIV/0! | W10: =1-T10/V10 -> #DIV/0! | X10: 6150000 | Y10: =IF(X10<>0,1-T10/X10," ") -> 0.33528455 | AA10: =IF(Z10<>0,Z10,R10) -> 4 | AB10: =IF(X10<>0, X10,V10) -> 6150000 | AC10: =AA10*AB10 -> 24600000 | AD10: 1
A11: =_xlfn.AGGREGATE(3,5,$B$5:B11) -> 7 | B11: Switch 16 port CISCO CBS110-16T-EU | C11: Cái | D11: 1 | E11: 2950000 | F11: =E11*D11 -> 2950000 | H11: 0.53 | I11: =ROUNDUP((E11+G11+E11*H11),-3) -> 4514000 | J11: =I11*D11 -> 4514000 | K11: =J11-F11 -> 1564000 | M11: 1499000 | N11: 0.05 | O11: =M11*(1-N11) -> 1424050 | P11: =O11/E11 -> 0.48272881 | R11: =D11 -> 1 | S11: =E11 -> 2950000 | T11: =I11 -> 4514000 | U11: =T11*R11 -> 4514000 | V11: =IF(AD11=1,U11*$U$2/R11+T11,T11) -> #DIV/0! | W11: =1-T11/V11 -> #DIV/0! | X11: 2150000 | Y11: =IF(X11<>0,1-T11/X11," ") -> -1.0995349 | AA11: =IF(Z11<>0,Z11,R11) -> 1 | AB11: =IF(X11<>0, X11,V11) -> 2150000 | AC11: =AA11*AB11 -> 2150000 | AD11: 1
A12: =_xlfn.AGGREGATE(3,5,$B$5:B12) -> 8 | B12: Màn hình quan sát SamSung 43inch | C12: Cái | D12: 4 | E12: 7400000 | F12: =E12*D12 -> 29600000 | H12: 0.15 | I12: =ROUNDUP((E12+G12+E12*H12),-3) -> 8510000 | J12: =I12*D12 -> 34040000 | K12: =J12-F12 -> 4440000 | R12: =D12 -> 4 | S12: =E12 -> 7400000 | T12: =I12 -> 8510000 | U12: =T12*R12 -> 34040000 | V12: =IF(AD12=1,U12*$U$2/R12+T12,T12) -> #DIV/0! | W12: =1-T12/V12 -> #DIV/0! | X12: 500000 | Y12: =IF(X12<>0,1-T12/X12," ") -> -16.02 | AA12: =IF(Z12<>0,Z12,R12) -> 4 | AB12: =IF(X12<>0, X12,V12) -> 500000 | AC12: =AA12*AB12 -> 2000000 | AD12: 1
A13: =_xlfn.AGGREGATE(3,5,$B$5:B13) -> 9 | B13: =[15]BOq!B26 -> Khung kệ tivi | C13: Cái | D13: 4 | E13: 150000 | F13: =E13*D13 -> 600000 | H13: 0.35 | I13: =ROUNDUP((E13+G13+E13*H13),-3) -> 203000 | J13: =I13*D13 -> 812000 | K13: =J13-F13 -> 212000 | P13: =O13/E13 -> 0 | R13: =D13 -> 4 | S13: =E13 -> 150000 | T13: =I13 -> 203000 | U13: =T13*R13 -> 812000 | V13: =IF(AD13=1,U13*$U$2/R13+T13,T13) -> #DIV/0! | W13: =1-T13/V13 -> #DIV/0! | Y13: =IF(X13<>0,1-T13/X13," ") | Z13: 600 | AA13: =IF(Z13<>0,Z13,R13) -> 600 | AB13: =IF(X13<>0, X13,V13) -> #DIV/0! | AC13: =AA13*AB13 -> #DIV/0! | AD13: 1
A14: =_xlfn.AGGREGATE(3,5,$B$5:B14) -> 10 | B14: =[15]BOq!B27 -> Cáp HDMI 15m Unitek | C14: Sợi | D14: 4 | E14: 400000 | F14: =E14*D14 -> 1600000 | H14: 0.4 | I14: =ROUNDUP((E14+G14+E14*H14),-3) -> 560000 | J14: =I14*D14 -> 2240000 | K14: =J14-F14 -> 640000 | M14: =3475000/305 -> 11393.443 | N14: 0.1 | O14: =M14*(1-N14) -> 10254.098 | P14: =O14/E14 -> 0.025635246 | R14: =D14 -> 4 | S14: =E14 -> 400000 | T14: =I14 -> 560000 | U14: =T14*R14 -> 2240000 | V14: =IF(AD14=1,U14*$U$2/R14+T14,T14) -> 560000 | W14: =1-T14/V14 -> 0 | Y14: =IF(X14<>0,1-T14/X14," ") | Z14: 3200 | AA14: =IF(Z14<>0,Z14,R14) -> 3200 | AB14: =IF(X14<>0, X14,V14) -> 560000 | AC14: =AA14*AB14 -> 1792000000
A15: II | B15: HẠNG MỤC TRUYỀN DẪN | F15: =SUBTOTAL(9,F16:F22) -> 58670980 | H15: =K15/F15 -> 0.80619107 | J15: =SUBTOTAL(9,J16:J22) -> 105971000 | K15: =SUBTOTAL(9,K16:K22) -> 47300020
A16: 1 | B16: Cáp quang 4FO | C16: Mét | D16: 400 | E16: 2300 | F16: =E16*D16 -> 920000 | H16: 1.4 | I16: =ROUNDUP((E16+G16+E16*H16),-2) -> 5600 | J16: =I16*D16 -> 2240000 | K16: =J16-F16 -> 1320000 | P16: =O16/E16 -> 0 | R16: =D16 -> 400 | S16: =E16 -> 2300 | T16: =I16 -> 5600 | U16: =T16*R16 -> 2240000 | V16: =IF(AD16=1,U16*$U$2/R16+T16,T16) -> #DIV/0! | W16: =1-T16/V16 -> #DIV/0! | X16: 34000 | Y16: =IF(X16<>0,1-T16/X16," ") -> 0.83529412 | AA16: =IF(Z16<>0,Z16,R16) -> 400 | AB16: =IF(X16<>0, X16,V16) -> 34000 | AC16: =AA16*AB16 -> 13600000 | AD16: 1
A17: 2 | B17: Cáp mạng Cat5E | C17: Mét | D17: =7300+360 -> 7660 | E17: 5803 | F17: =E17*D17 -> 44450980 | H17: 0.88 | I17: =ROUNDUP((E17+G17+E17*H17),-2) -> 11000 | J17: =I17*D17 -> 84260000 | K17: =J17-F17 -> 39809020 | R17: =D17 -> 7660 | S17: =E17 -> 5803 | T17: =I17 -> 11000 | U17: =T17*R17 -> 84260000 | V17: =IF(AD17=1,U17*$U$2/R17+T17,T17) -> 11000 | W17: =1-T17/V17 -> 0 | X17: 1050000 | Y17: =IF(X17<>0,1-T17/X17," ") -> 0.98952381 | AA17: =IF(Z17<>0,Z17,R17) -> 7660 | AB17: =IF(X17<>0, X17,V17) -> 1050000 | AC17: =AA17*AB17 -> 8043000000
A18: 3 | B18: Converter A/B 1000M | C18: Bộ | D18: 4 | E18: 600000 | F18: =E18*D18 -> 2400000 | H18: 0.8 | I18: =ROUNDUP((E18+G18+E18*H18),-3) -> 1080000 | J18: =I18*D18 -> 4320000 | K18: =J18-F18 -> 1920000 | O18: =M18*(1-N18) -> 0 | P18: =O18/E18 -> 0 | R18: =D18 -> 4 | S18: =E18 -> 600000 | T18: =I18 -> 1080000 | U18: =T18*R18 -> 4320000 | V18: =IF(AD18=1,U18*$U$2/R18+T18,T18) -> #DIV/0! | W18: =1-T18/V18 -> #DIV/0! | Y18: =IF(X18<>0,1-T18/X18," ") | AA18: =IF(Z18<>0,Z18,R18) -> 4 | AB18: =IF(X18<>0, X18,V18) -> #DIV/0! | AC18: =AA18*AB18 -> #DIV/0! | AD18: 1
A19: 4 | B19: Tủ mạng rack 6U | C19: Cái | D19: 2 | E19: 750000 | F19: =E19*D19 -> 1500000 | H19: 0.4 | I19: =ROUNDUP((E19+G19+E19*H19),-3) -> 1050000 | J19: =I19*D19 -> 2100000 | K19: =J19-F19 -> 600000 | M19: 2300000 | N19: 0.25 | O19: =M19*(1-N19) -> 1725000 | P19: =O19/E19 -> 2.3 | R19: =D19 -> 2 | S19: =E19 -> 750000 | T19: =I19 -> 1050000 | U19: =T19*R19 -> 2100000 | V19: =IF(AD19=1,U19*$U$2/R19+T19,T19) -> #DIV/0! | W19: =1-T19/V19 -> #DIV/0! | X19: 2590000 | Y19: =IF(X19<>0,1-T19/X19," ") -> 0.59459459 | AA19: =IF(Z19<>0,Z19,R19) -> 2 | AB19: =IF(X19<>0, X19,V19) -> 2590000 | AC19: =AA19*AB19 -> 5180000 | AD19: 1
A20: 5 | B20: Tủ mạng rack 10U | C20: Cái | D20: 2 | E20: 1400000 | F20: =E20*D20 -> 2800000 | H20: 0.36 | I20: =ROUNDUP((E20+G20+E20*H20),-3) -> 1904000 | J20: =I20*D20 -> 3808000 | K20: =J20-F20 -> 1008000 | M20: 2300000 | N20: 0.25 | O20: =M20*(1-N20) -> 1725000 | P20: =O20/E20 -> 1.2321429 | R20: =D20 -> 2 | S20: =E20 -> 1400000 | T20: =I20 -> 1904000 | U20: =T20*R20 -> 3808000 | V20: =IF(AD20=1,U20*$U$2/R20+T20,T20) -> #DIV/0! | W20: =1-T20/V20 -> #DIV/0! | X20: 2590000 | Y20: =IF(X20<>0,1-T20/X20," ") -> 0.26486486 | AA20: =IF(Z20<>0,Z20,R20) -> 2 | AB20: =IF(X20<>0, X20,V20) -> 2590000 | AC20: =AA20*AB20 -> 5180000 | AD20: 1
A21: 6 | B21: Tủ mạng rack 42U | C21: Cái | D21: 1 | E21: 6300000 | F21: =E21*D21 -> 6300000 | H21: 0.36 | I21: =ROUNDUP((E21+G21+E21*H21),-3) -> 8568000 | J21: =I21*D21 -> 8568000 | K21: =J21-F21 -> 2268000 | M21: =I21/32 -> 267750 | R21: =D21 -> 1 | S21: =E21 -> 6300000 | AA21: =IF(Z21<>0,Z21,R21) -> 1
A22: 7 | B22: ODF 12 FO | C22: Cái | D22: 1 | E22: 300000 | F22: =E22*D22 -> 300000 | H22: 1.25 | I22: =ROUNDUP((E22+G22+E22*H22),-3) -> 675000 | J22: =I22*D22 -> 675000 | K22: =J22-F22 -> 375000 | R22: =D22 -> 1 | AA22: =IF(Z22<>0,Z22,R22) -> 1
A23: III . | B23: HẠNG MỤC ĐIỆN | F23: =SUBTOTAL(9,F24:F25) -> 6456000 | H23: =K23/SUM(F23:F23) -> 0.19749071 | J23: =SUBTOTAL(9,J24:J25) -> 7731000 | K23: =SUBTOTAL(9,K24:K25) -> 1275000
A24: 1 | B24: Dây điện CVV 2x2.5 | C24: Mét | D24: 150 | E24: 24500 | F24: =E24*D24 -> 3675000 | H24: 0.08 | I24: =ROUNDUP((E24+G24+E24*H24),-2) -> 26500 | J24: =I24*D24 -> 3975000 | K24: =J24-F24 -> 300000 | M24: =2800/305 -> 9.1803279 | R24: =D24 -> 150 | S24: =E24 -> 24500 | T24: =I24 -> 26500 | U24: =T24*R24 -> 3975000 | V24: =IF(AD24=1,U24*$U$2/R24+T24,T24) -> #DIV/0! | W24: =1-T24/V24 -> #DIV/0! | X24: 5000 | Y24: =IF(X24<>0,1-T24/X24," ") -> -4.3 | Z24: 1350 | AA24: =IF(Z24<>0,Z24,R24) -> 1350 | AB24: =IF(X24<>0, X24,V24) -> 5000 | AC24: =AA24*AB24 -> 6750000 | AD24: 1
A25: 2 | B25: Thanh nguồn PDU đa năng 6 ổ cắm 3 chấu chuẩn 19" | C25: Cái | D25: 3 | E25: 927000 | F25: =E25*D25 -> 2781000 | H25: 0.35 | I25: =ROUNDUP((E25+G25+E25*H25),-3) -> 1252000 | J25: =I25*D25 -> 3756000 | K25: =J25-F25 -> 975000 | R25: =D25 -> 3 | S25: =E25 -> 927000 | T25: =I25 -> 1252000 | U25: =T25*R25 -> 3756000 | V25: =IF(AD25=1,U25*$U$2/R25+T25,T25) -> 1252000 | W25: =1-T25/V25 -> 0 | Y25: =IF(X25<>0,1-T25/X25," ") | AA25: =IF(Z25<>0,Z25,R25) -> 3 | AB25: =IF(X25<>0, X25,V25) -> 1252000 | AC25: =AA25*AB25 -> 3756000
A26: IV . | B26: HẠNG MỤC ĐIỆN DỰ PHÒNG | F26: =SUBTOTAL(9,F27:F29) -> 23408000 | H26: =K26/SUM(F26:F26) -> 0.22851162 | J26: =SUBTOTAL(9,J27:J29) -> 28757000 | K26: =SUBTOTAL(9,K27:K29) -> 5349000 | N26: =#REF!+#REF! -> #REF! | R26: =D26 -> 0 | U26: =T26*R26 -> 0 | V26: =IF(AD26=1,U26*$U$2/R26+T26,T26) -> 0 | Y26: =IF(X26<>0,1-T26/X26," ") | AA26: =IF(Z26<>0,Z26,R26) -> 0 | AB26: =IF(X26<>0, X26,V26) -> 0 | AC26: =AA26*AB26 -> 0
A27: 1 | B27: Nguồn lưu điện 2KVA UPS | C27: Bộ | D27: 2 | E27: 5607000 | F27: =E27*D27 -> 11214000 | H27: 0.24 | I27: =ROUNDUP((E27+G27+E27*H27),-3) -> 6953000 | J27: =I27*D27 -> 13906000 | K27: =J27-F27 -> 2692000 | R27: =D27 -> 2 | S27: =E27 -> 5607000 | T27: =I27 -> 6953000 | U27: =T27*R27 -> 13906000 | V27: =IF(AD27=1,U27*$U$2/R27+T27,T27) -> #DIV/0! | W27: =1-T27/V27 -> #DIV/0! | X27: 7120000 | Y27: =IF(X27<>0,1-T27/X27," ") -> 0.023455056 | AA27: =IF(Z27<>0,Z27,R27) -> 2 | AB27: =IF(X27<>0, X27,V27) -> 7120000 | AC27: =AA27*AB27 -> 14240000 | AD27: 1
A28: 2 | B28: Nguồn lưu điện 1K2VA UPS | C28: Bộ | D28: 2 | E28: 2170000 | F28: =E28*D28 -> 4340000 | H28: 0.25 | I28: =ROUNDUP((E28+G28+E28*H28),-3) -> 2713000 | J28: =I28*D28 -> 5426000 | K28: =J28-F28 -> 1086000 | R28: =D28 -> 2 | AA28: =IF(Z28<>0,Z28,R28) -> 2
A29: 3 | B29: Nguồn lưu điện 3KVA UPS | C29: Bộ | D29: 1 | E29: 7854000 | F29: =E29*D29 -> 7854000 | H29: 0.2 | I29: =ROUNDUP((E29+G29+E29*H29),-3) -> 9425000 | J29: =I29*D29 -> 9425000 | K29: =J29-F29 -> 1571000 | R29: =D29 -> 1 | AA29: =IF(Z29<>0,Z29,R29) -> 1
A30: IV. VẬT TƯ PHỤ | F30: =SUBTOTAL(9,F31:F35) -> 22682000 | H30: =K30/SUM(F30:F30) -> 0.46353937 | J30: =SUBTOTAL(9,J31:J35) -> 33196000 | K30: =SUBTOTAL(9,K31:K35) -> 10514000
A31: 1 | B31: Vật tư phụ | C31: Gói | D31: 1 | E31: 15000000 | F31: =E31*D31 -> 15000000 | H31: 0.4 | I31: =ROUNDUP((E31+G31+E31*H31),-3) -> 21000000 | J31: =I31*D31 -> 21000000 | K31: =J31-F31 -> 6000000 | R31: =D31 -> 1 | S31: =E31 -> 15000000 | T31: =I31 -> 21000000 | U31: =T31*R31 -> 21000000 | V31: =IF(AD31=1,U31*$U$2/R31+T31,T31) -> #DIV/0! | W31: =1-T31/V31 -> #DIV/0! | X31: 19500 | Y31: =IF(X31<>0,1-T31/X31," ") -> -1075.9231 | AA31: =IF(Z31<>0,Z31,R31) -> 1 | AB31: =IF(X31<>0, X31,V31) -> 19500 | AC31: =AA31*AB31 -> 19500 | AD31: 1
A32: 2 | B32: Dây nhảy quang SC-UPC/SC-UPC (3 Mét) | C32: Sợi | D32: 8 | E32: 19000 | F32: =E32*D32 -> 152000 | H32: 0.4 | I32: =ROUNDUP((E32+G32+E32*H32),-3) -> 27000 | J32: =I32*D32 -> 216000 | K32: =J32-F32 -> 64000 | P32: =O32/E32 -> 0 | R32: =D32 -> 8 | S32: =E32 -> 19000 | T32: =I32 -> 27000 | U32: =T32*R32 -> 216000 | V32: =IF(AD32=1,U32*$U$2/R32+T32,T32) -> #DIV/0! | W32: =1-T32/V32 -> #DIV/0! | X32: 160000 | Y32: =IF(X32<>0,1-T32/X32," ") -> 0.83125 | AA32: =IF(Z32<>0,Z32,R32) -> 8 | AB32: =IF(X32<>0, X32,V32) -> 160000 | AC32: =AA32*AB32 -> 1280000 | AD32: 1
A33: 3 | B33: Ruột gà phi 20 | C33: Mét | D33: 1700 | E33: =150000/50 -> 3000 | F33: =E33*D33 -> 5100000 | H33: 0.35 | I33: =ROUNDUP((E33+G33+E33*H33),-3) -> 5000 | J33: =I33*D33 -> 8500000 | K33: =J33-F33 -> 3400000 | R33: =D33 -> 1700 | S33: =E33 -> 3000 | T33: =I33 -> 5000 | U33: =T33*R33 -> 8500000 | V33: =IF(AD33=1,U33*$U$2/R33+T33,T33) -> #DIV/0! | W33: =1-T33/V33 -> #DIV/0! | Y33: =IF(X33<>0,1-T33/X33," ") | AA33: =IF(Z33<>0,Z33,R33) -> 1700 | AB33: =IF(X33<>0, X33,V33) -> #DIV/0! | AC33: =AA33*AB33 -> #DIV/0! | AD33: 1
A34: 4 | B34: ODF 2FO | C34: Cái | D34: 4 | E34: 30000 | F34: =E34*D34 -> 120000 | H34: 0.5 | I34: =ROUNDUP((E34+G34+E34*H34),-3) -> 45000 | J34: =I34*D34 -> 180000 | K34: =J34-F34 -> 60000 | M34: https://dienmayhoanghai.vn/tivi-samsung/smart-tivi-samsung-4k-50-inch-50au7002-uhd-moi-2022.html | R34: =D34 -> 4 | S34: =E34 -> 30000 | T34: =I34 -> 45000 | U34: =T34*R34 -> 180000 | V34: =IF(AD34=1,U34*$U$2/R34+T34,T34) -> 45000 | W34: =1-T34/V34 -> 0 | Y34: =IF(X34<>0,1-T34/X34," ") | AA34: =IF(Z34<>0,Z34,R34) -> 4 | AB34: =IF(X34<>0, X34,V34) -> 45000 | AC34: =AA34*AB34 -> 180000
A35: 5 | B35: Ống điện phi 20 | C35: Mét | D35: 330 | E35: 7000 | F35: =E35*D35 -> 2310000 | H35: 0.36 | I35: =ROUNDUP((E35+G35+E35*H35),-3) -> 10000 | J35: =I35*D35 -> 3300000 | K35: =J35-F35 -> 990000
A36: V. | B36: NHÂN CÔNG | C36: Công | D36: =SUM(D37:D39) -> 164 | E36: =F36/D36 -> 496981.71 | F36: =SUBTOTAL(9,F37:F43) -> 81505000 | H36: 0.36 | I36: =ROUNDUP((E36+G36+E36*H36),-3) -> 676000 | J36: =I36*D36 -> 110864000 | K36: =J36-F36 -> 29359000 | M36: =56/61 -> 0.91803279 | U36: =T36*R36 -> 0 | Y36: =IF(X36<>0,1-T36/X36," ") | AA36: =IF(Z36<>0,Z36,R36) -> 0 | AB36: =IF(X36<>0, X36,V36) -> 0 | AC36: =AA36*AB36 -> 0
A37: 1 | B37: Nhân công thi công | C37: Công | D37: =117+5 -> 122 | E37: 400000 | F37: =E37*D37 -> 48800000
A38: 2 | B38: Nhân công giám sát | C38: Công | D38: =39+1 -> 40 | E38: 500000 | F38: =E38*D38 -> 20000000
A39: 3 | B39: Công thiết kế, khảo sát | C39: Công | D39: 2 | E39: 450000 | F39: =E39*D39 -> 900000
A40: 4 | B40: Công báo giá, hồ sơ thầu | C40: Công | D40: 2 | E40: 450000 | F40: =E40*D40 -> 900000
...

Sheet UPDATE-94CAM
A2: KHỐI LƯỢNG BOQ GÓI 94 CAMERA LÔ G6
A4: STT | B4: VẬT TƯ | C4: MÔ TẢ | D4: Đ.VỊ | E4: SLG | F4: Nhân công | G4: Tổng nhân công | H4: GHI CHÚ
A5: I. HẠNG MỤC VẬT TƯ CHÍNH VÀ GIÁM SÁT VÀ ĐỊNH TUYẾN
A6: =_xlfn.AGGREGATE(3,3,$B$6:B6) -> 1 | B6: ='PTLL (2)'!B5 -> Camera IP Dome 2MP HIKVISION DS-2CD1121G0-I | C6: - Cảm biến ảnh: CMOS 1/2.9″ 2.0megapixel - Chuẩn nén H.265+/ H.265/ H.264+/ H.264 - Độ phân giải 1920×1080 - Tính năng lọc hồng ngoại ICR, 0lux với hồng ngoại - Ống kính 2.8mm | D6: =VLOOKUP(B6,'PTLL (2)'!$B$5:$J$42,2,0) -> Cái | E6: =Sheet3!O4 -> 94 | F6: 0.085 | G6: =E6*F6 -> 7.99
A7: =_xlfn.AGGREGATE(3,3,$B$6:B7) -> 2 | B7: ='PTLL (2)'!B7 -> Đầu ghi hình camera IP 32 kênh HIKVISION DS-7732NXI-K4 | C7: – Chuẩn nén H.265+/H.265/H.264+/H.264 – Hỗ trợ độ phân giải ghi hình lên đến 12MP – Băng thông đầu vào 256Mbps – Băng thông đầu ra 160Mbps – Hỗ trợ 4 ổ cứng, dung lượng tối đa mỗi ổ 10TB | D7: =VLOOKUP(B7,'PTLL (2)'!$B$5:$J$42,2,0) -> Cái | E7: 1 | F7: 0.12 | G7: =E7*F7 -> 0.12
A8: =_xlfn.AGGREGATE(3,3,$B$6:B8) -> 3 | B8: Đầu ghi hình camera IP 64 kênh HIKVISION DS-7764NXI-K4 | C8: – Chuẩn nén H.265+/H.265/H.264+/H.264 – Hỗ trợ độ phân giải ghi hình lên đến 32MP – Băng thông đầu vào 400Mbps – Băng thông đầu ra 400Mbps – Hỗ trợ 4 ổ cứng, dung lượng tối đa mỗi ổ 16TB | D8: Cái | E8: 1 | F8: 0.12 | G8: =E8*F8 -> 0.12
A9: =_xlfn.AGGREGATE(3,3,$B$6:B9) -> 4 | B9: Ổ Cứng 10T WESTERN | C9: - Ổ cứng HDD chuyên nghiệp cho camera. - Dung lượng: 10TB - Kết nối: SATA III | D9: Cái | E9: 6 | F9: 0.2 | G9: =E9*F9 -> 1.2
A10: =_xlfn.AGGREGATE(3,3,$B$6:B10) -> 5 | B10: ='PTLL (2)'!B9 -> Switch Hikvision POE 24 cổng DS-3E1326P-EI | C10: - Hỗ trợ 24 × 100Mbps PoE RJ45 ports, 2 × gigabit combos. - Cổng ưu tiên: Cổng 1 - 8. - Bảng địa chỉ MAC: 16K. - Khả năng chuyển mạch 8.8Gbps. - Tốc độ chuyển tiếp gói tin: 6.5472Mpps. - Truyền dẫn khoảng cách xa: Tối đa 300m ở chế độ mở rộng (cổng 1 – 24). - Tương thích chuẩn IEEE 802.3af/at. | D10: =VLOOKUP(B10,'PTLL (2)'!$B$5:$J$42,2,0) -> Cái | E10: =Sheet3!O5 -> 5 | F10: 0.18 | G10: =E10*F10 -> 0.9
A11: =_xlfn.AGGREGATE(3,3,$B$6:B11) -> 6 | B11: ='PTLL (2)'!B10 -> Switch Hikvision POE 16 cổng DS-3E1318P-EI | C11: -Switch mạng thông minh 16 cổng PoE. -Hỗ trợ tính năng cấu hình quản lý bằng phần mềm. -16 cổng PoE RJ45 100Mbps, 2 cổng RJ45 Gigabit, 2 cổng quang -Tự tương thích chuẩn IEEE 802.3af/at. | D11: =VLOOKUP(B11,'PTLL (2)'!$B$5:$J$42,2,0) -> Cái | E11: =Sheet3!O6 -> 1 | F11: 0.18 | G11: =E11*F11 -> 0.18
A12: =_xlfn.AGGREGATE(3,3,$B$6:B12) -> 7 | B12: ='PTLL (2)'!B11 -> Switch 16 port CISCO CBS110-16T-EU | C12: - Hỗ trợ 16 cổng Gigabit Ethernet RJ-45 | D12: =VLOOKUP(B12,'PTLL (2)'!$B$5:$J$42,2,0) -> Cái | E12: 1 | F12: 0.18 | G12: =E12*F12 -> 0.18
A13: =_xlfn.AGGREGATE(3,3,$B$6:B13) -> 8 | B13: Màn hình quan sát 43 inch SamSung(khung kệ + HDMI (15m)) | D13: Bộ | E13: 1 | F13: 0.34 | G13: =E13*F13 -> 0.34
A14: =_xlfn.AGGREGATE(3,3,$B$6:B14) -> 8 | B14: ='PTLL (2)'!B12 -> Màn hình quan sát SamSung 43inch | D14: =VLOOKUP(B14,'PTLL (2)'!$B$5:$J$42,2,0) -> Cái | E14: =VLOOKUP(B14,'PTLL (2)'!$B$5:$J$42,3,0) -> 4 | F14: 0.34 | G14: =E14*F14 -> 1.36
A15: =_xlfn.AGGREGATE(3,3,$B$6:B15) -> 8 | B15: ='PTLL (2)'!B13 -> Khung kệ tivi | D15: =VLOOKUP(B15,'PTLL (2)'!$B$5:$J$42,2,0) -> Cái | E15: =VLOOKUP(B15,'PTLL (2)'!$B$5:$J$42,3,0) -> 4 | F15: 0.34 | G15: =E15*F15 -> 1.36
A16: =_xlfn.AGGREGATE(3,3,$B$6:B16) -> 8 | B16: ='PTLL (2)'!B14 -> Cáp HDMI 15m Unitek | D16: =VLOOKUP(B16,'PTLL (2)'!$B$5:$J$42,2,0) -> Sợi | E16: =VLOOKUP(B16,'PTLL (2)'!$B$5:$J$42,3,0) -> 4 | F16: 0.34 | G16: =E16*F16 -> 1.36
A17: =_xlfn.AGGREGATE(3,3,$B$6:B17) -> 9 | B17: Màn hình quan sát 55 inch SamSung(khung kệ + HDMI (15m)) | D17: Bộ | E17: 1 | F17: 0.34 | G17: =E17*F17 -> 0.34
A18: II. HẠNG MỤC TRUYỀN DẪN
A19: 1 | B19: ='PTLL (2)'!B16 -> Cáp quang 4FO | D19: =VLOOKUP(B19,'PTLL (2)'!$B$5:$J$42,2,0) -> Mét | E19: 300 | F19: 0.007 | G19: =E19*F19 -> 2.1
A20: 2 | B20: ='PTLL (2)'!B17 -> Cáp mạng Cat5E | D20: =VLOOKUP(B20,'PTLL (2)'!$B$5:$J$42,2,0) -> Mét | E20: 2800 | F20: 0.01 | G20: =E20*F20 -> 28 | H20: LS/Panduit/Comspose
A21: 3 | B21: Bộ chuyển đổi quang điện Gigabit GNETCOM 10/100/1000M GNC-2111S-20A/B | D21: Bộ | E21: =Sheet3!R5 -> 2 | F21: 0.018 | G21: =E21*F21 -> 0.036
A22: 5 | B22: Tủ mạng rack 10U( Có bánh xe) | D22: Bộ | E22: =Sheet3!R3 -> 2 | F22: 0.765 | G22: =E22*F22 -> 1.53
A23: 6 | B23: Tủ mạng rack 42U | D23: Bộ | E23: 1 | F23: 0 | G23: =E23*F23 -> 0 | H23: Tận dụng hiện hữu
A24: 7 | B24: ODF 12FO SC/UPC (Full Phụ kiện) | D24: Cái | E24: 1 | F24: 1 | G24: =E24*F24 -> 1
A25: III. HẠNG MỤC ĐIỆN
A26: 1 | B26: ='PTLL (2)'!B24 -> Dây điện CVV 2x2.5 | D26: =VLOOKUP(B26,'PTLL (2)'!$B$5:$J$42,2,0) -> Mét | E26: 20 | F26: 0.01 | G26: =E26*F26 -> 0.2
A27: 2 | B27: ='PTLL (2)'!B25 -> Thanh nguồn PDU đa năng 6 ổ cắm 3 chấu chuẩn 19" | D27: =VLOOKUP(B27,'PTLL (2)'!$B$5:$J$42,2,0) -> Cái | E27: =Sheet3!R4+1 -> 3 | F27: 0.04 | G27: =E27*F27 -> 0.12 | H27: Dintek/Vietrack/TMC
A28: IV. HẠNG MỤC NGUỒN DỰ PHÒNG
A29: 1 | B29: Nguồn lưu điện UPS ARES Model AR610 1000VA/800W | D29: Bộ | E29: =Sheet3!R6 -> 2 | F29: 0.245 | G29: =E29*F29 -> 0.49
A30: 3 | B30: Nguồn lưu điện UPS ARES Model AR630 3000VA-2400W | D30: Bộ | E30: 1 | F30: 0.245 | G30: =E30*F30 -> 0.245
A31: V. VẬT TƯ PHỤ
A32: 1 | B32: ='[16]ptll 61 cam'!B29 -> Vật tư phụ | C32: Bao gồm ống điện, ruột gà, vít, tacke… | D32: =VLOOKUP(B32,'[16]ptll 61 cam'!$B$6:$K$35,4,0) -> Gói | E32: =VLOOKUP(B32,'[16]ptll 61 cam'!$B$6:$K$35,5,0) -> 1
A33: 1.1 | B33: Vật tư phụ kết nối | D33: Gói | E33: 1
B34: Đầu mạng AMP Cat 5 | D34: Cái | E34: 300 | F34: =0.04*2/3 -> 0.026666667 | G34: =E34*F34 -> 8
B35: Dây nhảy quang SC/UPC SC/UPC 3M | D35: Sợi | E35: =E22*2 -> 4 | F35: 0.013 | G35: =E35*F35 -> 0.052
B36: ODF 4FO SC/UPC - SC/UPC (Full phụ kiện) | D36: Bộ | E36: =E22 -> 2 | F36: 0.165 | G36: =E36*F36 -> 0.33
B37: Dây nhảy mạng Cat5 | D37: Sợi | E37: =E35+E7+E12 -> 6 | F37: 0.013 | G37: =E37*F37 -> 0.078 | H37: Dintek/AMP/Panduit
B38: Thanh quản lý cáp mạng 19inch | D38: Cái | E38: =E22+2 -> 4 | F38: 0.08 | G38: =E38*F38 -> 0.32 | H38: Dintek/AMP/Panduit
A39: 1.2 | B39: Vật tư phụ thi công | H39: Dự trù 10 triệu chưa bao gồm 1.2.1 và 1.2.2
A40: 1.2.1 | B40: Ruột gà | D40: Mét | E40: =55/2*23 -> 632.5 | F40: 0.034 | G40: =E40*F40 -> 21.505
A41: 1.2.2 | B41: Ống phi 20 | D41: Mét | E41: 30 | F41: 0.034 | G41: =E41*F41 -> 1.02
A42: VI. CHI PHÍ LẮP ĐẶT
...

Sheet UPDATE_CONGSUAT
A1: BẢNG CHÀO GIÁ (Số: 157.2025/BG-TSI-SRR.E) | D1: CÔNG TY CỔ PHẦN ĐẦU TƯ VÀ XÂY DỰNG THIÊN SỨ
A2: Hạng mục: Cung cấp thiết bị và lắp đặt hệ thống 132 camera | D2: 72-74 Phổ Quang, P. Tân Sơn Hòa, Tp.HCM
D3: ĐT: 08.3866.3582
A4: Kính gửi: Ban quản lý dự án Sunrise Riverside lô E | D4: info@thiensu.com.vn -www.thiensu.com.vn
A5: Địa chỉ :Xã Phước Kiển, Huyện Nhà bè, Tp.HCM | D5: PHÒNG KINH DOANH
A6: Đại diện: Khách hàng | D6: 070 234 2009
A8: STT | B8: VẬT TƯ | C8: MÔ TẢ | D8: Đ.VỊ | E8: SLG | F8: ĐƠN GIÁ (VNĐ) | G8: THÀNH TIỀN (VNĐ) | H8: GHI CHÚ
A9: I. HẠNG MỤC VẬT TƯ CHÍNH VÀ GIÁM SÁT VÀ ĐỊNH TUYẾN | G9: =SUBTOTAL(9,G10:G20) -> 287610000
A10: =_xlfn.AGGREGATE(3,3,$B$10:B10) -> 1 | B10: ='PTLL (2)'!B5 -> Camera IP Dome 2MP HIKVISION DS-2CD1121G0-I | C10: - Cảm biến ảnh: CMOS 1/2.9″ 2.0megapixel - Chuẩn nén H.265+/ H.265/ H.264+/ H.264 - Độ phân giải 1920×1080 - Tính năng lọc hồng ngoại ICR, 0lux với hồng ngoại - Ống kính 2.8mm - Công suất : 6.5W | D10: =VLOOKUP(B10,'PTLL (2)'!$B$5:$J$42,2,0) -> Cái | E10: =VLOOKUP(B10,'PTLL (3)'!$B$5:$J$42,3,0) -> 118 | F10: =VLOOKUP(B10,'PTLL (3)'!$B$5:$J$43,8,0) -> 786000 | G10: =E10*F10 -> 92748000
A11: =_xlfn.AGGREGATE(3,3,$B$10:B11) -> 2 | B11: ='PTLL (2)'!B6 -> Camera IP thân 2MP HIKVISION DS-2CD1021G0-I | C11: - Cảm biến ảnh: CMOS 1/2.9″ 2.0megapixel - Chuẩn nén H.265+/ H.265/ H.264+/ H.264 - Độ phân giải 1920×1080 - Tính năng lọc hồng ngoại ICR, 0lux với hồng ngoại - Ống kính 2.8mm - Công suất : 6.5W | D11: =VLOOKUP(B11,'PTLL (2)'!$B$5:$J$42,2,0) -> Cái | E11: =VLOOKUP(B11,'PTLL (3)'!$B$5:$J$42,3,0) -> 14 | F11: =VLOOKUP(B11,'PTLL (3)'!$B$5:$J$43,8,0) -> 745000 | G11: =E11*F11 -> 10430000
A12: =_xlfn.AGGREGATE(3,3,$B$10:B12) -> 3 | B12: ='PTLL (2)'!B7 -> Đầu ghi hình camera IP 32 kênh HIKVISION DS-7732NXI-K4 | C12: – Chuẩn nén H.265+/H.265/H.264+/H.264 – Hỗ trợ độ phân giải ghi hình lên đến 12MP – Băng thông đầu vào 256Mbps – Băng thông đầu ra 160Mbps – Hỗ trợ 4 ổ cứng, dung lượng tối đa mỗi ổ 10TB - Công suất 20W | D12: =VLOOKUP(B12,'PTLL (2)'!$B$5:$J$42,2,0) -> Cái | E12: 6 | F12: =VLOOKUP(B12,'PTLL (3)'!$B$5:$J$43,8,0) -> 9643000 | G12: =E12*F12 -> 57858000
A13: =_xlfn.AGGREGATE(3,3,$B$10:B13) -> 4 | B13: ='PTLL (2)'!B8 -> Ổ Cứng 8T WESTERN | C13: - Ổ cứng HDD chuyên nghiệp cho camera. - Dung lượng: 8TB - Kết nối: SATA III - Cache: 256MB - Công suất : 5.3W | D13: =VLOOKUP(B13,'PTLL (2)'!$B$5:$J$42,2,0) -> Cái | E13: =VLOOKUP(B13,'PTLL (3)'!$B$5:$J$42,3,0) -> 8 | F13: =VLOOKUP(B13,'PTLL (3)'!$B$5:$J$43,8,0) -> 6015000 | G13: =E13*F13 -> 48120000
A14: =_xlfn.AGGREGATE(3,3,$B$10:B14) -> 5 | B14: ='PTLL (2)'!B9 -> Switch Hikvision POE 24 cổng DS-3E1326P-EI | C14: - Hỗ trợ 24 × 100Mbps PoE RJ45 ports, 2 × gigabit combos. - Cổng ưu tiên: Cổng 1 - 8. - Bảng địa chỉ MAC: 16K. - Khả năng chuyển mạch 8.8Gbps. - Tốc độ chuyển tiếp gói tin: 6.5472Mpps. - Truyền dẫn khoảng cách xa: Tối đa 300m ở chế độ mở rộng (cổng 1 – 24). - Tương thích chuẩn IEEE 802.3af/at. - Công suất PoE: 370W. | D14: =VLOOKUP(B14,'PTLL (2)'!$B$5:$J$42,2,0) -> Cái | E14: =VLOOKUP(B14,'PTLL (3)'!$B$5:$J$42,3,0) -> 4 | F14: =VLOOKUP(B14,'PTLL (3)'!$B$5:$J$43,8,0) -> 5124000 | G14: =E14*F14 -> 20496000
A15: =_xlfn.AGGREGATE(3,3,$B$10:B15) -> 6 | B15: ='PTLL (2)'!B10 -> Switch Hikvision POE 16 cổng DS-3E1318P-EI | C15: -Switch mạng thông minh 16 cổng PoE. -Hỗ trợ tính năng cấu hình quản lý bằng phần mềm. -16 cổng PoE RJ45 100Mbps, 2 cổng RJ45 Gigabit, 2 cổng quang -Tự tương thích chuẩn IEEE 802.3af/at. - Công suất PoE 230W. | D15: =VLOOKUP(B15,'PTLL (2)'!$B$5:$J$42,2,0) -> Cái | E15: =VLOOKUP(B15,'PTLL (3)'!$B$5:$J$42,3,0) -> 4 | F15: =VLOOKUP(B15,'PTLL (3)'!$B$5:$J$43,8,0) -> 4088000 | G15: =E15*F15 -> 16352000
A16: =_xlfn.AGGREGATE(3,3,$B$10:B16) -> 7 | B16: ='PTLL (2)'!B11 -> Switch 16 port CISCO CBS110-16T-EU | C16: - Hỗ trợ 16 cổng Gigabit Ethernet RJ-45 - Công suất : 9.96W | D16: =VLOOKUP(B16,'PTLL (2)'!$B$5:$J$42,2,0) -> Cái | E16: =VLOOKUP(B16,'PTLL (3)'!$B$5:$J$42,3,0) -> 1 | F16: =VLOOKUP(B16,'PTLL (3)'!$B$5:$J$43,8,0) -> 4514000 | G16: =E16*F16 -> 4514000
A17: 8 | B17: Màn hình quan sát 43 inch SamSung+ khung kệ + HDMI | D17: Bộ | E17: 4 | F17: =SUM('PTLL (3)'!I12:I14) -> 9273000 | G17: =E17*F17 -> 37092000
A18: 8.1 | B18: ='PTLL (2)'!B12 -> Màn hình quan sát SamSung 43inch | D18: =VLOOKUP(B18,'PTLL (2)'!$B$5:$J$42,2,0) -> Cái | E18: =VLOOKUP(B18,'PTLL (2)'!$B$5:$J$42,3,0) -> 4
A19: 8.2 | B19: ='PTLL (2)'!B13 -> Khung kệ tivi | D19: =VLOOKUP(B19,'PTLL (2)'!$B$5:$J$42,2,0) -> Cái | E19: =VLOOKUP(B19,'PTLL (2)'!$B$5:$J$42,3,0) -> 4
A20: 8.3 | B20: ='PTLL (2)'!B14 -> Cáp HDMI 15m Unitek | D20: =VLOOKUP(B20,'PTLL (2)'!$B$5:$J$42,2,0) -> Sợi | E20: =VLOOKUP(B20,'PTLL (2)'!$B$5:$J$42,3,0) -> 4
A21: II. HẠNG MỤC TRUYỀN DẪN | G21: =SUBTOTAL(9,G22:G28) -> 105971000
A22: 1 | B22: ='PTLL (2)'!B16 -> Cáp quang 4FO | D22: =VLOOKUP(B22,'PTLL (2)'!$B$5:$J$42,2,0) -> Mét | E22: =VLOOKUP(B22,'PTLL (3)'!$B$5:$J$42,3,0) -> 400 | F22: =VLOOKUP(B22,'PTLL (3)'!$B$5:$J$43,8,0) -> 5600 | G22: =E22*F22 -> 2240000
A23: 2 | B23: ='PTLL (2)'!B17 -> Cáp mạng Cat5E | D23: =VLOOKUP(B23,'PTLL (2)'!$B$5:$J$42,2,0) -> Mét | E23: =VLOOKUP(B23,'PTLL (3)'!$B$5:$J$42,3,0) -> 7660 | F23: =VLOOKUP(B23,'PTLL (3)'!$B$5:$J$43,8,0) -> 11000 | G23: =E23*F23 -> 84260000
A24: 3 | B24: ='PTLL (2)'!B18 -> Converter A/B 1000M | D24: =VLOOKUP(B24,'PTLL (2)'!$B$5:$J$42,2,0) -> Bộ | E24: =VLOOKUP(B24,'PTLL (3)'!$B$5:$J$42,3,0) -> 4 | F24: =VLOOKUP(B24,'PTLL (3)'!$B$5:$J$43,8,0) -> 1080000 | G24: =E24*F24 -> 4320000
A25: 4 | B25: ='PTLL (2)'!B19 -> Tủ mạng rack 6U | D25: =VLOOKUP(B25,'PTLL (2)'!$B$5:$J$42,2,0) -> Cái | E25: =VLOOKUP(B25,'PTLL (3)'!$B$5:$J$42,3,0) -> 2 | F25: =VLOOKUP(B25,'PTLL (3)'!$B$5:$J$43,8,0) -> 1050000 | G25: =E25*F25 -> 2100000
A26: 5 | B26: ='PTLL (2)'!B20 -> Tủ mạng rack 10U | D26: =VLOOKUP(B26,'PTLL (2)'!$B$5:$J$42,2,0) -> Cái | E26: =VLOOKUP(B26,'PTLL (3)'!$B$5:$J$42,3,0) -> 2 | F26: =VLOOKUP(B26,'PTLL (3)'!$B$5:$J$43,8,0) -> 1904000 | G26: =E26*F26 -> 3808000
A27: 6 | B27: ='PTLL (2)'!B21 -> Tủ mạng rack 42U | D27: =VLOOKUP(B27,'PTLL (2)'!$B$5:$J$42,2,0) -> Cái | E27: =VLOOKUP(B27,'PTLL (3)'!$B$5:$J$42,3,0) -> 1 | F27: =VLOOKUP(B27,'PTLL (3)'!$B$5:$J$43,8,0) -> 8568000 | G27: =E27*F27 -> 8568000
A28: 7 | B28: ='PTLL (2)'!B22 -> ODF 12 FO | D28: =VLOOKUP(B28,'PTLL (2)'!$B$5:$J$42,2,0) -> Cái | E28: =VLOOKUP(B28,'PTLL (3)'!$B$5:$J$42,3,0) -> 1 | F28: =VLOOKUP(B28,'PTLL (3)'!$B$5:$J$43,8,0) -> 675000 | G28: =E28*F28 -> 675000
A29: III. HẠNG MỤC ĐIỆN | G29: =SUBTOTAL(9,G30:G31) -> 7731000
A30: 1 | B30: ='PTLL (2)'!B24 -> Dây điện CVV 2x2.5 | D30: =VLOOKUP(B30,'PTLL (2)'!$B$5:$J$42,2,0) -> Mét | E30: =VLOOKUP(B30,'PTLL (3)'!$B$5:$J$42,3,0) -> 150 | F30: =VLOOKUP(B30,'PTLL (3)'!$B$5:$J$43,8,0) -> 26500 | G30: =E30*F30 -> 3975000
A31: 2 | B31: ='PTLL (2)'!B25 -> Thanh nguồn PDU đa năng 6 ổ cắm 3 chấu chuẩn 19" | D31: =VLOOKUP(B31,'PTLL (2)'!$B$5:$J$42,2,0) -> Cái | E31: =VLOOKUP(B31,'PTLL (3)'!$B$5:$J$42,3,0) -> 3 | F31: =VLOOKUP(B31,'PTLL (3)'!$B$5:$J$43,8,0) -> 1252000 | G31: =E31*F31 -> 3756000
A32: IV. HẠNG MỤC NGUỒN DỰ PHÒNG | G32: =SUBTOTAL(9,G33:G35) -> 28757000
A33: 1 | B33: ='PTLL (2)'!B27 -> Nguồn lưu điện 2KVA UPS | D33: =VLOOKUP(B33,'PTLL (2)'!$B$5:$J$42,2,0) -> Bộ | E33: =VLOOKUP(B33,'PTLL (3)'!$B$5:$J$42,3,0) -> 2 | F33: =VLOOKUP(B33,'PTLL (3)'!$B$5:$J$43,8,0) -> 6953000 | G33: =E33*F33 -> 13906000
A34: 2 | B34: ='PTLL (2)'!B28 -> Nguồn lưu điện 1K2VA UPS | D34: =VLOOKUP(B34,'PTLL (2)'!$B$5:$J$42,2,0) -> Bộ | E34: =VLOOKUP(B34,'PTLL (3)'!$B$5:$J$42,3,0) -> 2 | F34: =VLOOKUP(B34,'PTLL (3)'!$B$5:$J$43,8,0) -> 2713000 | G34: =E34*F34 -> 5426000
A35: 3 | B35: ='PTLL (2)'!B29 -> Nguồn lưu điện 3KVA UPS | D35: =VLOOKUP(B35,'PTLL (2)'!$B$5:$J$42,2,0) -> Bộ | E35: =VLOOKUP(B35,'PTLL (3)'!$B$5:$J$42,3,0) -> 1 | F35: =VLOOKUP(B35,'PTLL (3)'!$B$5:$J$43,8,0) -> 9425000 | G35: =E35*F35 -> 9425000
A36: V. VẬT TƯ PHỤ | G36: =SUBTOTAL(9,G37) -> 33196000
A37: 1 | B37: ='[16]ptll 61 cam'!B29 -> Vật tư phụ | C37: Bao gồm ống điện, ruột gà, vít, tacke | D37: =VLOOKUP(B37,'[16]ptll 61 cam'!$B$6:$K$35,4,0) -> Gói | E37: =VLOOKUP(B37,'[16]ptll 61 cam'!$B$6:$K$35,5,0) -> 1 | F37: ='PTLL (3)'!J30 -> 33196000 | G37: =E37*F37 -> 33196000
A38: VI. CHI PHÍ LẮP ĐẶT | G38: =SUBTOTAL(9,G39) -> 110864000
A39: 1 | B39: Chi phí lắp đặt | C39: Thi công trọn gói và hướng dẫn vận hành | D39: Gói | E39: 1 | F39: ='PTLL (3)'!J36 -> 110864000 | G39: =F39*E39 -> 110864000
A40: TỔNG GIÁ TRỊ CHƯA VAT | G40: =SUBTOTAL(9,G9:G39) -> 574129000
A41: VAT 10% | G41: =G40*0.1 -> 57412900
...

Sheet TÓM TẮT BG
A1: TÓM TẮT BÁO GIÁ CUNG CẤP VÀ LẮP ĐẶT THIẾT BỊ HỆ THỐNG 127 CAMERA DỰ ÁN SUNRISE RIVERSDIE LÔ E
A2: STT | B2: NGÀY BÁO GIÁ | C2: NỘI DUNG BÁO GIÁ | D2: CHI PHÍ ĐẦU TƯ CHƯA VAT | G2: DOANH THU CHƯA VAT | J2: CP HỖ TRỢ | P2: LN RÒNG | Q2: LN RÒNG/ CPĐT | R2: LN RÒNG/ DT | S2: GHI CHÚ
J3: BQL | N3: BQT (3%) | O3: TỔNG CP HỖ TRỢ
D4: VẬT TƯ | E4: NHÂN CÔNG | F4: TỔNG CHI PHÍ | G4: VẬT TƯ | H4: NHÂN CÔNG | I4: TỔNG DOANH THU | J4: KST | K4: PM | L4: KT | M4: TỔNG CHI PHÍ BQL
A5: 1 | B5: 45844 | C5: Báo giá thi công 127 Camera | D5: 2.8326798e+08 | E5: 73365000 | F5: 3.5663298e+08 | G5: 386368000 | H5: 99840000 | I5: 486208000 | J5: 4000000 | K5: 4000000 | M5: 8000000 | N5: 14586240 | O5: 22586240 | P5: 73314880 | Q5: 0.20557516 | R5: 0.15078913 | S5: Thi công 39 ngày
A6: 2 | B6: 19/09/2025 | C6: Báo giá thi công 127 Camera | D6: 303961900 | E6: 73365000 | F6: 377326900 | G6: 435789000 | H6: 99840000 | I6: 535629000 | J6: 4000000 | K6: 4000000 | M6: 8000000 | N6: 16068870 | O6: 24068870 | P6: 94681915 | Q6: 0.25092808 | R6: 0.17676772 | S6: Thi công 39 ngày
A7: 3 | B7: 26/09/2025 | C7: Báo giá thi công 132 Camera | D7: ='PTLL (3)'!C54 -> 308950980 | E7: ='PTLL (3)'!C56 -> 81505000 | F7: =E7+D7 -> 390455980 | G7: ='PTLL (3)'!J44-'PTLL (3)'!J36 -> 443979000 | H7: ='PTLL (3)'!J36 -> 110864000 | I7: =H7+G7 -> 554843000 | J7: 4000000 | K7: 4000000 | M7: 8000000 | N7: ='PTLL (3)'!C60 -> 16645290 | O7: =N7+M7 -> 24645290 | P7: ='PTLL (3)'!C71 -> 98696329 | Q7: =P7/F7 -> 0.25277197 | R7: =P7/I7 -> 0.17788154 | S7: Thi công 39 ngày
A8: Chênh lệch báo giá đợt (3)-(2) | F8: =F7-F6 -> 13129080 | I8: =I7-I6 -> 19214000 | O8: =O7-O6 -> 576420 | P8: =P7-P6 -> 4014414.6 | Q8: =Q7-Q6 -> 0.0018438947 | R8: =R7-R6 -> 0.001113828
P9: 45926
C10: Giám đốc | F10: Kinh Doạnh | K10: Kiểm Soát | P10: Người lập
C15: Nguyễn Hữu Ngọc | F15: Nguyễn Quang Tuấn | K15: Võ Thị Hồng Huệ | P15: Nguyễn Thị Trà Giang
E73: ='PTLL (3)'!C56 -> 81505000
E74: ='PTLL (3)'!C71 -> 98696329

Sheet bgct
A1: BẢNG CHÀO GIÁ (Số: 92.2025/BG-TSI-SRR.E) | D1: CÔNG TY CỔ PHẦN ĐẦU TƯ VÀ XÂY DỰNG THIÊN SỨ
A2: Hạng mục: Cung cấp thiết bị và lắp đặt hệ thống 127camera | D2: 72-74 Phổ Quang, Phường 2, Q.Tân Bình, Tp.HCM
D3: ĐT: 08.3866.3582
A4: Kính gửi: Ban quản lý dự án Sunrise Riverside lô E | D4: info@thiensu.com.vn -www.thiensu.com.vn
A5: Địa chỉ :Xã Phước Kiển, Huyện Nhà bè, Tp.HCM | D5: PHÒNG KINH DOANH
A6: Đại diện: Khách hàng | D6: Mr Truân - 0938 916 602
I7: 0.12 | M7: 0.15
A8: STT | B8: Vật tư | C8: Mô tả | D8: Đơn vị | E8: Số lượng | F8: Đơn giá | G8: Thành tiền | H8: Ghi chú | I8: 58344960 | J8: =I8/$G$40 -> 0.12 | M8: =G40*15% -> 72931200 | N8: =M8/$G$40 -> 0.15
A9: I. HẠNG MỤC VẬT TƯ CHÍNH VÀ GIÁM SÁT VÀ ĐỊNH TUYẾN | G9: =SUBTOTAL(9,G10:G20) -> 233711000 | I9: =J40-G40 -> 58344960 | J9: =I8-I9 -> 0 | N9: =M8-M9 -> 72931200
A10: =_xlfn.AGGREGATE(3,3,$B$10:B10) -> 1 | B10: ='PTLL (2)'!B5 -> Camera IP Dome 2MP HIKVISION DS-2CD1121G0-I | C10: Camera IP Dome 2MP - Cảm biến ảnh: CMOS 1/2.9″ 2.0megapixel - Chuẩn nén H.265+/ H.265/ H.264+/ H.264 - Độ phân giải 1920×1080 - Tính năng lọc hồng ngoại ICR, 0lux với hồng ngoại - Ống kính 2.8mm - Công suất : 6.5W | D10: =VLOOKUP(B10,'PTLL (2)'!$B$5:$J$42,2,0) -> Cái | E10: =VLOOKUP(B10,'PTLL (2)'!$B$5:$J$42,3,0) -> 113 | F10: =VLOOKUP(B10,'PTLL (2)'!$B$5:$J$42,8,0) -> 650000 | G10: =E10*F10 -> 73450000 | I10: =G10*(1+$J$8)/E10 -> 728000 | J10: =I10*E10 -> 82264000 | K10: 730000 | L10: =K10*E10 -> 82490000 | M10: =G10*(1+$M$7)/E10 -> 747500 | N10: =M10*E10 -> 84467500 | O10: 805000 | P10: =O10*E10 -> 90965000
A11: =_xlfn.AGGREGATE(3,3,$B$10:B11) -> 2 | B11: ='PTLL (2)'!B6 -> Camera IP thân 2MP HIKVISION DS-2CD1021G0-I | C11: Camera IP thân 2MP '- Cảm biến ảnh: CMOS 1/2.9″ 2.0megapixel - Chuẩn nén H.265+/ H.265/ H.264+/ H.264 - Độ phân giải 1920×1080 - Tính năng lọc hồng ngoại ICR, 0lux với hồng ngoại - Ống kính 2.8mm - Công suất : 6.5W | D11: =VLOOKUP(B11,'PTLL (2)'!$B$5:$J$42,2,0) -> Cái | E11: =VLOOKUP(B11,'PTLL (2)'!$B$5:$J$42,3,0) -> 14 | F11: =VLOOKUP(B11,'PTLL (2)'!$B$5:$J$42,8,0) -> 633000 | G11: =E11*F11 -> 8862000 | I11: =G11*(1+$J$8)/E11 -> 708960 | J11: =I11*E11 -> 9925440 | K11: 710000 | L11: =K11*E11 -> 9940000 | M11: =G11*(1+$M$7)/E11 -> 727950 | N11: =M11*E11 -> 10191300 | O11: 805000 | P11: =O11*E11 -> 11270000
A12: =_xlfn.AGGREGATE(3,3,$B$10:B12) -> 3 | B12: ='PTLL (2)'!B7 -> Đầu ghi hình camera IP 32 kênh HIKVISION DS-7732NXI-K4 | C12: Đầu ghi hình camera IP 32 kênh '– Chuẩn nén H.265+/H.265/H.264+/H.264 – Hỗ trợ độ phân giải ghi hình lên đến 12MP – Băng thông đầu vào 256Mbps – Băng thông đầu ra 160Mbps – Hỗ trợ 4 ổ cứng, dung lượng tối đa mỗi ổ 10TB - Công suất 20W | D12: =VLOOKUP(B12,'PTLL (2)'!$B$5:$J$42,2,0) -> Cái | E12: =VLOOKUP(B12,'PTLL (2)'!$B$5:$J$42,3,0) -> 4 | F12: =VLOOKUP(B12,'PTLL (2)'!$B$5:$J$42,8,0) -> 8649000 | G12: =E12*F12 -> 34596000 | I12: =G12*(1+$J$8)/E12 -> 9686880 | J12: =I12*E12 -> 38747520 | K12: 9340000 | L12: =K12*E12 -> 37360000 | M12: =G12*(1+$M$7)/E12 -> 9946350 | N12: =M12*E12 -> 39785400 | O12: 8950000 | P12: =O12*E12 -> 35800000
A13: =_xlfn.AGGREGATE(3,3,$B$10:B13) -> 4 | B13: ='PTLL (2)'!B8 -> Ổ Cứng 8T WESTERN | C13: - Ổ cứng 8TB HDD chuyên nghiệp cho camera. - Dung lượng: 8TB - Kết nối: SATA III - Cache: 256MB - Công suất : 5.3W | D13: =VLOOKUP(B13,'PTLL (2)'!$B$5:$J$42,2,0) -> Cái | E13: =VLOOKUP(B13,'PTLL (2)'!$B$5:$J$42,3,0) -> 8 | F13: =VLOOKUP(B13,'PTLL (2)'!$B$5:$J$42,8,0) -> 5350000 | G13: =E13*F13 -> 42800000 | I13: =G13*(1+$J$8)/E13 -> 5992000 | J13: =I13*E13 -> 47936000 | K13: =I13 -> 5992000 | L13: =K13*E13 -> 47936000 | M13: =G13*(1+$M$7)/E13 -> 6152500 | N13: =M13*E13 -> 49220000 | O13: 5980000 | P13: =O13*E13 -> 47840000
A14: =_xlfn.AGGREGATE(3,3,$B$10:B14) -> 5 | B14: ='PTLL (2)'!B9 -> Switch Hikvision POE 24 cổng DS-3E1326P-EI | C14: Swtich POE 24 cổng - Hỗ trợ 24 × 100Mbps PoE RJ45 ports, 2 × gigabit combos. - Cổng ưu tiên: Cổng 1 - 8. - Bảng địa chỉ MAC: 16K. - Khả năng chuyển mạch 8.8Gbps. - Tốc độ chuyển tiếp gói tin: 6.5472Mpps. - Tương thích chuẩn IEEE 802.3af/at. - Công suất PoE: 370W. | D14: =VLOOKUP(B14,'PTLL (2)'!$B$5:$J$42,2,0) -> Cái | E14: =VLOOKUP(B14,'PTLL (2)'!$B$5:$J$42,3,0) -> 4 | F14: =VLOOKUP(B14,'PTLL (2)'!$B$5:$J$42,8,0) -> 4524000 | G14: =E14*F14 -> 18096000 | I14: =G14*(1+$J$8)/E14 -> 5066880 | J14: =I14*E14 -> 20267520 | K14: =5077000 -> 5077000 | L14: =K14*E14 -> 20308000 | M14: =G14*(1+$M$7)/E14 -> 5202600 | N14: =M14*E14 -> 20810400 | O14: 4670000 | P14: =O14*E14 -> 18680000
A15: =_xlfn.AGGREGATE(3,3,$B$10:B15) -> 6 | B15: ='PTLL (2)'!B10 -> Switch Hikvision POE 16 cổng DS-3E1318P-EI | C15: - Switch mạng thông minh 16 cổng PoE. - Hỗ trợ tính năng cấu hình quản lý bằng phần mềm. -16 cổng PoE RJ45 100Mbps, 2 cổng RJ45 Gigabit, 2 cổng quang -Tự tương thích chuẩn IEEE 802.3af/at. - Công suất PoE 230W. | D15: =VLOOKUP(B15,'PTLL (2)'!$B$5:$J$42,2,0) -> Cái | E15: =VLOOKUP(B15,'PTLL (2)'!$B$5:$J$42,3,0) -> 4 | F15: =VLOOKUP(B15,'PTLL (2)'!$B$5:$J$42,8,0) -> 3962000 | G15: =E15*F15 -> 15848000 | I15: =G15*(1+$J$8)/E15 -> 4437440 | J15: =I15*E15 -> 17749760 | K15: 4438000 | L15: =K15*E15 -> 17752000 | M15: =G15*(1+$M$7)/E15 -> 4556300 | N15: =M15*E15 -> 18225200 | O15: 4270000 | P15: =O15*E15 -> 17080000
A16: =_xlfn.AGGREGATE(3,3,$B$10:B16) -> 7 | B16: ='PTLL (2)'!B11 -> Switch 16 port CISCO CBS110-16T-EU | C16: Switch 16 port - Hỗ trợ 16 cổng Gigabit Ethernet RJ-45 - Công suất : 9.96W | D16: =VLOOKUP(B16,'PTLL (2)'!$B$5:$J$42,2,0) -> Cái | E16: =VLOOKUP(B16,'PTLL (2)'!$B$5:$J$42,3,0) -> 1 | F16: =VLOOKUP(B16,'PTLL (2)'!$B$5:$J$42,8,0) -> 3475000 | G16: =E16*F16 -> 3475000 | I16: =G16*(1+$J$8)/E16 -> 3892000 | J16: =I16*E16 -> 3892000 | K16: =I16 -> 3892000 | L16: =K16*E16 -> 3892000 | M16: =G16*(1+$M$7)/E16 -> 3996250 | N16: =M16*E16 -> 3996250 | O16: 3997000 | P16: =O16*E16 -> 3997000
A17: 8 | B17: Màn hình quan sát 43 inch SamSung+ khung kệ + HDMI | D17: Bộ | E17: 4 | F17: =SUM('PTLL (2)'!I12:I14) -> 9146000 | G17: =E17*F17 -> 36584000 | I17: =G17*(1+$J$8)/E17 -> 10243520 | J17: =I17*E17 -> 40974080 | K17: 9000000 | L17: =K17*E17 -> 36000000 | M17: =G17*(1+$M$7)/E17 -> 10517900 | N17: =M17*E17 -> 42071600 | O17: 9250000 | P17: =O17*E17 -> 37000000
A18: 8.1 | B18: ='PTLL (2)'!B12 -> Màn hình quan sát SamSung 43inch | D18: =VLOOKUP(B18,'PTLL (2)'!$B$5:$J$42,2,0) -> Cái | E18: =VLOOKUP(B18,'PTLL (2)'!$B$5:$J$42,3,0) -> 4 | I18: =G18*(1+$J$8)/E18 -> 0 | J18: =I18*E18 -> 0 | L18: =K18*E18 -> 0 | M18: =G18*(1+$M$7)/E18 -> 0 | N18: =M18*E18 -> 0 | P18: =O18*I18 -> 0
A19: 8.2 | B19: ='PTLL (2)'!B13 -> Khung kệ tivi | D19: =VLOOKUP(B19,'PTLL (2)'!$B$5:$J$42,2,0) -> Cái | E19: =VLOOKUP(B19,'PTLL (2)'!$B$5:$J$42,3,0) -> 4 | I19: =G19*(1+$J$8)/E19 -> 0 | J19: =I19*E19 -> 0 | K19: 500000 | L19: =K19*E19 -> 2000000 | M19: =G19*(1+$M$7)/E19 -> 0 | N19: =M19*E19 -> 0 | O19: 500000 | P19: =O19*I19 -> 0
A20: 8.3 | B20: ='PTLL (2)'!B14 -> Cáp HDMI 15m Unitek | D20: =VLOOKUP(B20,'PTLL (2)'!$B$5:$J$42,2,0) -> Sợi | E20: =VLOOKUP(B20,'PTLL (2)'!$B$5:$J$42,3,0) -> 4 | I20: =G20*(1+$J$8)/E20 -> 0 | J20: =I20*E20 -> 0 | K20: 700000 | L20: =K20*E20 -> 2800000 | M20: =G20*(1+$M$7)/E20 -> 0 | N20: =M20*E20 -> 0 | O20: 700000 | P20: =O20*I20 -> 0
A21: II. HẠNG MỤC TRUYỀN DẪN | G21: =SUBTOTAL(9,G22:G28) -> 86116000 | J21: =I21*E21 -> 0 | N21: =M21*E21 -> 0
A22: 1 | B22: ='PTLL (2)'!B16 -> Cáp quang 4FO | D22: =VLOOKUP(B22,'PTLL (2)'!$B$5:$J$42,2,0) -> Mét | E22: =VLOOKUP(B22,'PTLL (2)'!$B$5:$J$42,3,0) -> 400 | F22: =VLOOKUP(B22,'PTLL (2)'!$B$5:$J$42,8,0) -> 5600 | G22: =E22*F22 -> 2240000 | I22: =G22*(1+$J$8)/E22 -> 6272 | J22: =I22*E22 -> 2508800 | K22: 6000 | L22: =K22*E22 -> 2400000 | M22: =G22*(1+$M$7)/E22 -> 6440 | N22: =M22*E22 -> 2576000 | O22: 6000 | P22: =O22*E22 -> 2400000
A23: 2 | B23: ='PTLL (2)'!B17 -> Cáp mạng Cat5E | D23: =VLOOKUP(B23,'PTLL (2)'!$B$5:$J$42,2,0) -> Mét | E23: =VLOOKUP(B23,'PTLL (2)'!$B$5:$J$42,3,0) -> 7300 | F23: =VLOOKUP(B23,'PTLL (2)'!$B$5:$J$42,8,0) -> 9000 | G23: =E23*F23 -> 65700000 | I23: =G23*(1+$J$8)/E23 -> 10080 | J23: =I23*E23 -> 73584000 | K23: 10500 | L23: =K23*E23 -> 76650000 | M23: =G23*(1+$M$7)/E23 -> 10350 | N23: =M23*E23 -> 75555000 | O23: 10500 | P23: =O23*E23 -> 76650000
A24: 3 | B24: ='PTLL (2)'!B18 -> Converter A/B 1000M | D24: =VLOOKUP(B24,'PTLL (2)'!$B$5:$J$42,2,0) -> Bộ | E24: =VLOOKUP(B24,'PTLL (2)'!$B$5:$J$42,3,0) -> 4 | F24: =VLOOKUP(B24,'PTLL (2)'!$B$5:$J$42,8,0) -> 1080000 | G24: =E24*F24 -> 4320000 | I24: =G24*(1+$J$8)/E24 -> 1209600 | J24: =I24*E24 -> 4838400 | K24: 1380000 | L24: =K24*E24 -> 5520000 | M24: =G24*(1+$M$7)/E24 -> 1242000 | N24: =M24*E24 -> 4968000 | O24: 1280000 | P24: =O24*E24 -> 5120000
A25: 4 | B25: ='PTLL (2)'!B19 -> Tủ mạng rack 6U | D25: =VLOOKUP(B25,'PTLL (2)'!$B$5:$J$42,2,0) -> Cái | E25: =VLOOKUP(B25,'PTLL (2)'!$B$5:$J$42,3,0) -> 2 | F25: =VLOOKUP(B25,'PTLL (2)'!$B$5:$J$42,8,0) -> 1015000 | G25: =E25*F25 -> 2030000 | I25: =G25*(1+$J$8)/E25 -> 1136800 | J25: =I25*E25 -> 2273600 | K25: 1250000 | L25: =K25*E25 -> 2500000 | M25: =G25*(1+$M$7)/E25 -> 1167250 | N25: =M25*E25 -> 2334500 | O25: 1200000 | P25: =O25*E25 -> 2400000
A26: 5 | B26: ='PTLL (2)'!B20 -> Tủ mạng rack 10U | D26: =VLOOKUP(B26,'PTLL (2)'!$B$5:$J$42,2,0) -> Cái | E26: =VLOOKUP(B26,'PTLL (2)'!$B$5:$J$42,3,0) -> 2 | F26: =VLOOKUP(B26,'PTLL (2)'!$B$5:$J$42,8,0) -> 1638000 | G26: =E26*F26 -> 3276000 | I26: =G26*(1+$J$8)/E26 -> 1834560 | J26: =I26*E26 -> 3669120 | K26: 1760000 | L26: =K26*E26 -> 3520000 | M26: =G26*(1+$M$7)/E26 -> 1883700 | N26: =M26*E26 -> 3767400 | O26: 1780000 | P26: =O26*E26 -> 3560000
A27: 6 | B27: ='PTLL (2)'!B21 -> Tủ mạng rack 42U | D27: =VLOOKUP(B27,'PTLL (2)'!$B$5:$J$42,2,0) -> Cái | E27: =VLOOKUP(B27,'PTLL (2)'!$B$5:$J$42,3,0) -> 1 | F27: =VLOOKUP(B27,'PTLL (2)'!$B$5:$J$42,8,0) -> 7875000 | G27: =E27*F27 -> 7875000 | I27: =G27*(1+$J$8)/E27 -> 8820000 | J27: =I27*E27 -> 8820000 | K27: =I27 -> 8820000 | L27: =K27*E27 -> 8820000 | M27: =G27*(1+$M$7)/E27 -> 9056250 | N27: =M27*E27 -> 9056250 | O27: 8900000 | P27: =O27*E27 -> 8900000
A28: 7 | B28: ='PTLL (2)'!B22 -> ODF 12 FO | D28: =VLOOKUP(B28,'PTLL (2)'!$B$5:$J$42,2,0) -> Cái | E28: =VLOOKUP(B28,'PTLL (2)'!$B$5:$J$42,3,0) -> 1 | F28: =VLOOKUP(B28,'PTLL (2)'!$B$5:$J$42,8,0) -> 675000 | G28: =E28*F28 -> 675000 | I28: =G28*(1+$J$8)/E28 -> 756000 | J28: =I28*E28 -> 756000 | K28: 750000 | L28: =K28*E28 -> 750000 | M28: =G28*(1+$M$7)/E28 -> 776250 | N28: =M28*E28 -> 776250 | O28: 785000 | P28: =O28*E28 -> 785000
A29: III. HẠNG MỤC ĐIỆN | G29: =SUBTOTAL(9,G30:G31) -> 6360000 | J29: =I29*E29 -> 0 | N29: =M29*E29 -> 0
A30: 1 | B30: ='PTLL (2)'!B24 -> Dây điện CVV 2x2.5 | D30: =VLOOKUP(B30,'PTLL (2)'!$B$5:$J$42,2,0) -> Mét | E30: 150 | F30: =VLOOKUP(B30,'PTLL (2)'!$B$5:$J$42,8,0) -> 21800 | G30: =E30*F30 -> 3270000 | I30: =G30*(1+$J$8)/E30 -> 24416 | J30: =I30*E30 -> 3662400 | K30: 23000 | L30: =K30*200 -> 4600000 | M30: =G30*(1+$M$7)/E30 -> 25070 | N30: =M30*E30 -> 3760500 | O30: 23500 | P30: =O30*200 -> 4700000
A31: 2 | B31: ='PTLL (2)'!B25 -> Thanh nguồn PDU đa năng 6 ổ cắm 3 chấu chuẩn 19" | D31: =VLOOKUP(B31,'PTLL (2)'!$B$5:$J$42,2,0) -> Cái | E31: =VLOOKUP(B31,'PTLL (2)'!$B$5:$J$42,3,0) -> 3 | F31: =VLOOKUP(B31,'PTLL (2)'!$B$5:$J$42,8,0) -> 1030000 | G31: =E31*F31 -> 3090000 | I31: =G31*(1+$J$8)/E31 -> 1153600 | J31: =I31*E31 -> 3460800 | K31: 1080000 | L31: =K31*E31 -> 3240000 | M31: =G31*(1+$M$7)/E31 -> 1184500 | N31: =M31*E31 -> 3553500 | O31: 1320000 | P31: =O31*E31 -> 3960000
A32: IV. HẠNG MỤC NGUỒN DỰ PHÒNG | G32: =SUBTOTAL(9,G33:G35) -> 27285000 | J32: =I32*E32 -> 0 | N32: =M32*E32 -> 0
A33: 1 | B33: ='PTLL (2)'!B27 -> Nguồn lưu điện 2KVA UPS | D33: =VLOOKUP(B33,'PTLL (2)'!$B$5:$J$42,2,0) -> Bộ | E33: =VLOOKUP(B33,'PTLL (2)'!$B$5:$J$42,3,0) -> 2 | F33: =VLOOKUP(B33,'PTLL (2)'!$B$5:$J$42,8,0) -> 6478000 | G33: =E33*F33 -> 12956000 | I33: =G33*(1+$J$8)/E33 -> 7255360 | J33: =I33*E33 -> 14510720 | K33: 6980000 | L33: =K33*E33 -> 13960000 | M33: =G33*(1+$M$7)/E33 -> 7449700 | N33: =M33*E33 -> 14899400 | O33: 6980000 | P33: =O33*E33 -> 13960000
A34: 2 | B34: ='PTLL (2)'!B28 -> Nguồn lưu điện 1K2VA UPS | D34: =VLOOKUP(B34,'PTLL (2)'!$B$5:$J$42,2,0) -> Bộ | E34: =VLOOKUP(B34,'PTLL (2)'!$B$5:$J$42,3,0) -> 2 | F34: =VLOOKUP(B34,'PTLL (2)'!$B$5:$J$42,8,0) -> 2707000 | G34: =E34*F34 -> 5414000 | I34: =G34*(1+$J$8)/E34 -> 3031840 | J34: =I34*E34 -> 6063680 | K34: 3020000 | L34: =K34*E34 -> 6040000 | M34: =G34*(1+$M$7)/E34 -> 3113050 | N34: =M34*E34 -> 6226100 | O34: 3020000 | P34: =O34*E34 -> 6040000
A35: 3 | B35: ='PTLL (2)'!B29 -> Nguồn lưu điện 3KVA UPS | D35: =VLOOKUP(B35,'PTLL (2)'!$B$5:$J$42,2,0) -> Bộ | E35: =VLOOKUP(B35,'PTLL (2)'!$B$5:$J$42,3,0) -> 1 | F35: =VLOOKUP(B35,'PTLL (2)'!$B$5:$J$42,8,0) -> 8915000 | G35: =E35*F35 -> 8915000 | I35: =G35*(1+$J$8)/E35 -> 9984800 | J35: =I35*E35 -> 9984800 | K35: 9640000 | L35: =K35*E35 -> 9640000 | M35: =G35*(1+$M$7)/E35 -> 10252250 | N35: =M35*E35 -> 10252250 | O35: 9640000 | P35: =O35*E35 -> 9640000
A36: IV. VẬT TƯ PHỤ | G36: =SUBTOTAL(9,G37) -> 32896000 | J36: =I36*E36 -> 0 | N36: =M36*E36 -> 0
A37: 1 | B37: ='[16]ptll 61 cam'!B29 -> Vật tư phụ | C37: Bao gồm ống điện, ruột gà, vít, tacke | D37: =VLOOKUP(B37,'[16]ptll 61 cam'!$B$6:$K$35,4,0) -> Gói | E37: =VLOOKUP(B37,'[16]ptll 61 cam'!$B$6:$K$35,5,0) -> 1 | F37: ='PTLL (2)'!J30 -> 32896000 | G37: =E37*F37 -> 32896000 | I37: =G37*(1+$J$8)/E37 -> 36843520 | J37: =I37*E37 -> 36843520 | K37: 36700000 | L37: =K37*E37 -> 36700000 | M37: =G37*(1+$M$7)/E37 -> 37830400 | N37: =M37*E37 -> 37830400 | O37: 37500000 | P37: =O37*E37 -> 37500000
A38: V. CHI PHÍ LẮP ĐẶT | G38: =SUBTOTAL(9,G39) -> 99840000 | J38: =I38*E38 -> 0 | N38: =M38*E38 -> 0
A39: 1 | B39: Chi phí lắp đặt | C39: Thi công trọn gói và hướng dẫn vận hành | D39: Gói | E39: 1 | F39: ='PTLL (2)'!J36 -> 99840000 | G39: =F39*E39 -> 99840000 | I39: =G39*(1+$J$8)/E39 -> 1.118208e+08 | J39: =I39*E39 -> 1.118208e+08 | K39: 112000000 | L39: =K39*E39 -> 112000000 | M39: =G39*(1+$M$7)/E39 -> 1.14816e+08 | N39: =M39*E39 -> 1.14816e+08 | O39: 115800000 | P39: =O39*E39 -> 115800000
A40: TỔNG GIÁ TRỊ CHƯA VAT | G40: =SUBTOTAL(9,G9:G39) -> 486208000 | J40: =SUBTOTAL(9,J10:J39) -> 544552960 | L40: =SUBTOTAL(9,L10:L39) -> 546818000 | N40: =SUBTOTAL(9,N10:N39) -> 559139200 | P40: =SUBTOTAL(9,P10:P39) -> 554047000
...

Sheet Sheet1
A2: BẢNG CHÀO GIÁ
A3: Hạng mục: Hệ thống 127 Camera
A4: Kính gửi: Ban quản lý dự án Sunrise Riverside lô E
A5: Địa chỉ :Xã Phước Kiển, Huyện Nhà bè, Tp.HCM
A7: STT | B7: Vật tư | C7: Mô tả | D7: Công suất | E7: Đơn vị | F7: Số lượng | G7: Đơn giá | H7: Thành tiền | I7: Ghi chú
A8: I. VẬT TƯ THIẾT BỊ CHÍNH | H8: =SUBTOTAL(9,H9:H16) -> 267432000
A9: =_xlfn.AGGREGATE(3,3,$B$9:B9) -> 1 | B9: ='PTLL (2)'!B5 -> Camera IP Dome 2MP HIKVISION DS-2CD1121G0-I | C9: Camera IP Dome 2MP - Cảm biến ảnh: CMOS 1/2.9″ 2.0megapixel - Chuẩn nén H.265+/ H.265/ H.264+/ H.264 - Độ phân giải 1920×1080 - Tính năng lọc hồng ngoại ICR, 0lux với hồng ngoại - Ống kính 2.8mm | D9: 6.5W | E9: =VLOOKUP(B9,'PTLL (2)'!$B$5:$J$42,2,0) -> Cái | F9: =VLOOKUP(B9,'PTLL (2)'!$B$5:$J$42,3,0) -> 113 | G9: =VLOOKUP(B9,bgct!$B$10:$O$39,14,0) -> 805000 | H9: =F9*G9 -> 90965000
A10: =_xlfn.AGGREGATE(3,3,$B$9:B10) -> 2 | B10: ='PTLL (2)'!B6 -> Camera IP thân 2MP HIKVISION DS-2CD1021G0-I | C10: Camera IP thân 2MP - Cảm biến ảnh: CMOS 1/2.9″ 2.0megapixel - Chuẩn nén H.265+/ H.265/ H.264+/ H.264 - Độ phân giải 1920×1080 - Tính năng lọc hồng ngoại ICR, 0lux với hồng ngoại - Ống kính 2.8mm | D10: 6.5W | E10: =VLOOKUP(B10,'PTLL (2)'!$B$5:$J$42,2,0) -> Cái | F10: =VLOOKUP(B10,'PTLL (2)'!$B$5:$J$42,3,0) -> 14 | G10: =VLOOKUP(B10,bgct!$B$10:$O$39,14,0) -> 805000 | H10: =F10*G10 -> 11270000
A11: =_xlfn.AGGREGATE(3,3,$B$9:B11) -> 3 | B11: ='PTLL (2)'!B7 -> Đầu ghi hình camera IP 32 kênh HIKVISION DS-7732NXI-K4 | C11: Đầu ghi hình camera IP 32 kênh – Chuẩn nén H.265+/H.265/H.264+/H.264 – Hỗ trợ độ phân giải ghi hình lên đến 12MP – Băng thông đầu vào 256Mbps – Băng thông đầu ra 160Mbps – Hỗ trợ 4 ổ cứng, dung lượng tối đa mỗi ổ 10TB | D11: 20W | E11: =VLOOKUP(B11,'PTLL (2)'!$B$5:$J$42,2,0) -> Cái | F11: =VLOOKUP(B11,'PTLL (2)'!$B$5:$J$42,3,0) -> 4 | G11: =VLOOKUP(B11,bgct!$B$10:$O$39,14,0) -> 8950000 | H11: =F11*G11 -> 35800000
A12: =_xlfn.AGGREGATE(3,3,$B$9:B12) -> 4 | B12: ='PTLL (2)'!B8 -> Ổ Cứng 8T WESTERN | C12: - Ổ cứng 8TB HDD chuyên nghiệp cho camera. - Dung lượng: 8TB - Kết nối: SATA III - Cache: 256MB | D12: 5.3W | E12: =VLOOKUP(B12,'PTLL (2)'!$B$5:$J$42,2,0) -> Cái | F12: =VLOOKUP(B12,'PTLL (2)'!$B$5:$J$42,3,0) -> 8 | G12: =VLOOKUP(B12,bgct!$B$10:$O$39,14,0) -> 5980000 | H12: =F12*G12 -> 47840000
A13: =_xlfn.AGGREGATE(3,3,$B$9:B13) -> 5 | B13: ='PTLL (2)'!B9 -> Switch Hikvision POE 24 cổng DS-3E1326P-EI | C13: Swtich POE 24 cổng - Hỗ trợ 24 × 100Mbps PoE RJ45 ports, 2 × gigabit combos. - Cổng ưu tiên: Cổng 1 - 8. - Bảng địa chỉ MAC: 16K. - Khả năng chuyển mạch 8.8Gbps. - Tốc độ chuyển tiếp gói tin: 6.5472Mpps. - Tương thích chuẩn IEEE 802.3af/at. | D13: 370W | E13: =VLOOKUP(B13,'PTLL (2)'!$B$5:$J$42,2,0) -> Cái | F13: =VLOOKUP(B13,'PTLL (2)'!$B$5:$J$42,3,0) -> 4 | G13: =VLOOKUP(B13,bgct!$B$10:$O$39,14,0) -> 4670000 | H13: =F13*G13 -> 18680000
A14: =_xlfn.AGGREGATE(3,3,$B$9:B14) -> 6 | B14: ='PTLL (2)'!B10 -> Switch Hikvision POE 16 cổng DS-3E1318P-EI | C14: - Switch mạng thông minh 16 cổng PoE. - Hỗ trợ tính năng cấu hình quản lý bằng phần mềm. -16 cổng PoE RJ45 100Mbps, 2 cổng RJ45 Gigabit, 2 cổng quang -Tự tương thích chuẩn IEEE 802.3af/at. | D14: 230W | E14: =VLOOKUP(B14,'PTLL (2)'!$B$5:$J$42,2,0) -> Cái | F14: =VLOOKUP(B14,'PTLL (2)'!$B$5:$J$42,3,0) -> 4 | G14: =VLOOKUP(B14,bgct!$B$10:$O$39,14,0) -> 4270000 | H14: =F14*G14 -> 17080000
