Workbook
Name _?: #REF!
Name _??????: #REF!
Name __abb91: [1]chitimc!#REF!
Name __CT250: '[1]dongia (2)'!#REF!
Name __ddn400: #REF!
Name __ddn600: #REF!
Name __dgt100: '[1]dongia (2)'!#REF!
Name __MAC12: #REF!
Name __MAC46: #REF!
Name __NCL100: #REF!
Name __NCL200: #REF!
Name __NCL250: #REF!
Name __nin190: [2]VC!#REF!
Name __sc1: #REF!
Name __SC2: #REF!
Name __sc3: [2]VC!#REF!
Name __SN3: #REF!
Name __th100: '[1]dongia (2)'!#REF!
Name __TH160: '[1]dongia (2)'!#REF!
Name __TL1: #REF!
Name __TL2: #REF!
Name __TL3: #REF!
Name __TLA120: #REF!
Name __TLA35: #REF!
Name __TLA50: #REF!
Name __TLA70: #REF!
Name __TLA95: #REF!
Name __TR250: '[1]dongia (2)'!#REF!
Name __tr375: [1]giathanh1!#REF!
Name __VL100: #REF!
Name __VL200: #REF!
Name _1_?: #REF!
Name _2_??????: #REF!
Name _abb91: [1]chitimc!#REF!
Name _CT250: '[1]dongia (2)'!#REF!
Name _ddn400: #REF!
Name _ddn600: #REF!
Name _dgt100: '[1]dongia (2)'!#REF!
Name _MAC12: #REF!
Name _MAC46: #REF!
Name _NCL100: #REF!
Name _NCL200: #REF!
Name _NCL250: #REF!
Name _nin190: [3]VC!#REF!
Name _sc1: #REF!
Name _SC2: #REF!
Name _sc3: [3]VC!#REF!
Name _SN3: #REF!
Name _th100: '[1]dongia (2)'!#REF!
Name _TH160: '[1]dongia (2)'!#REF!
Name _TL1: #REF!
Name _TL2: #REF!
Name _TL3: #REF!
Name _TLA120: #REF!
Name _TLA35: #REF!
Name _TLA50: #REF!
Name _TLA70: #REF!
Name _TLA95: #REF!
Name _TR250: '[1]dongia (2)'!#REF!
Name _tr375: [1]giathanh1!#REF!

Sheet BOQ
N2: TỔNG CAMERA | O2: =L13+Y13 -> 0 | Q2: TỦ 2U | R2: =G13+U13 -> 0
N3: Camera Thân | O3: =J13+W13 -> 0 | Q3: TỦ 6U | R3: =H13 -> 0
N4: Camera Dome | O4: =K13+X13 -> 0 | Q4: PDU | R4: =C13+Q13 -> 0
N5: SWPOE 24 | O5: =E13+S13 -> 0 | Q5: Converter | R5: =B13+P13 -> 0
N6: SWPOE 16 | O6: =F13+T13 -> 0 | Q6: UPS 610 | R6: =D13+R13 -> 0
Q7: Tổng mét cáp | R7: =SUM(J14,W14) -> 0
B9: THÁP I
F11: I
B12: Converter | C12: PDU | D12: UPS AR610 1K | E12: SW 24 | F12: SW16 | G12: TU 2U | H12: TU 6U | I12: CAM VỀ TỦ | J12: CAMERA THAN | K12: Camera DOME | L12: Tổng CAM | M12: TANG | N12: Mét cáp
B13: =SUM(B14:B52) -> 0 | C13: =SUM(C14:C52) -> 0 | D13: =SUM(D14:D52) -> 0 | E13: =SUM(E14:E52) -> 0 | F13: =SUM(F14:F52) -> 0 | G13: =SUM(G14:G52) -> 0 | H13: =SUM(H14:H52) -> 0 | I13: =SUM(I14:I52) -> 0 | ... K13: =SUM(K14:K52) -> 0 | L13: =J13+K13 -> 0 | N13: ='tính cáp'!J44 -> 0

Sheet BOM
A2: KHỐI LƯỢNG BOQ
D3: Ngày update: 16.07.2026
B6: Công triển khai căn cứ vào bảng khối lượng nhân công
A7: STT | B7: VẬT TƯ | C7: MÔ TẢ | D7: Đ.VỊ | E7: SLG | F7: Nhân công | G7: Tổng nhân công | H7: GHI CHÚ
A8: I. HẠNG MỤC VẬT TƯ CHÍNH VÀ GIÁM SÁT VÀ ĐỊNH TUYẾN
A9: =_xlfn.AGGREGATE(3,3,$B$9:B9) -> 1 | B9: Camera IP Dome 2MP HIKVISION DS-2CD1121G0-I | C9: - Cảm biến ảnh: CMOS 1/2.9″ 2.0megapixel - Chuẩn nén H.265+/ H.265/ H.264+/ H.264 - Độ phân giải 1920×1080 - Tính năng lọc hồng ngoại ICR, 0lux với hồng ngoại - Ống kính 2.8mm - Công suất tiêu thụ tối đa: 6,5W | D9: Cái | F9: 0.085
A10: =_xlfn.AGGREGATE(3,3,$B$9:B10) -> 2 | B10: Camera IP thân 2MP HIKVISION DS-2CD1021G0-I | C10: - Cảm biến ảnh: CMOS 1/2.9″ 2.0megapixel - Chuẩn nén H.265+/ H.265/ H.264+/ H.264 - Độ phân giải 1920×1080 - Tính năng lọc hồng ngoại ICR, 0lux với hồng ngoại - Ống kính 2.8/4mm - Công suất tiêu thụ tối đa: 6,5W | D10: Cái | F10: 0.085
A11: =_xlfn.AGGREGATE(3,3,$B$9:B11) -> 3 | B11: Đầu ghi hình camera IP 16 kênh HIKVISION DS-7716NXI-K4 | C11: – Chuẩn nén H.265+/H.265/H.264+/H.264 – Hỗ trợ độ phân giải ghi hình lên đến 12MP – Băng thông đầu vào 160Mbps – Băng thông đầu ra 160Mbps – Hỗ trợ 4 ổ cứng, dung lượng tối đa mỗi ổ 10TB - Công suất tiêu thụ tối đa: ≤ 20 W (Không HDD) | D11: Cái | F11: 0.12
A12: =_xlfn.AGGREGATE(3,3,$B$9:B12) -> 4 | B12: Đầu ghi hình camera IP 32 kênh HIKVISION DS-7732NXI-K4 | C12: – Chuẩn nén H.265+/H.265/H.264+/H.264 – Hỗ trợ độ phân giải ghi hình lên đến 12MP – Băng thông đầu vào 256Mbps – Băng thông đầu ra 160Mbps – Hỗ trợ 4 ổ cứng, dung lượng tối đa mỗi ổ 10TB - Công suất tiêu thụ tối đa: ≤ 20 W (Không HDD) | D12: Cái | F12: 0.12
A13: =_xlfn.AGGREGATE(3,3,$B$9:B13) -> 5 | B13: Ổ Cứng 10T WESTERN WD101PURP | C13: - Ổ cứng HDD chuyên nghiệp cho camera. - Dung lượng: 10TB - Kết nối: SATA III - Công suất tiêu thụ tối đa: 9W | D13: Cái | F13: 0.2
A14: =_xlfn.AGGREGATE(3,3,$B$9:B14) -> 6 | B14: Switch Hikvision POE 16 cổng DS-3E1318P-EI | C14: -Switch mạng thông minh 16 cổng PoE. -Hỗ trợ tính năng cấu hình quản lý bằng phần mềm. -16 cổng PoE RJ45 100Mbps, 2 cổng RJ45 Gigabit, 2 cổng quang -Tự tương thích chuẩn IEEE 802.3af/at. - Công suất tiêu thụ tối đa: 250W | D14: Cái | F14: 0.18
A15: =_xlfn.AGGREGATE(3,3,$B$9:B15) -> 7 | B15: Switch Hikvision POE 24 cổng DS-3E1326P-EI | C15: -Switch mạng thông minh 24 cổng PoE. - Hỗ trợ tính năng cấu hình quản lý bằng phần mềm. - 24 cổng PoE RJ45 100Mbps , 2 cổng RJ45 Gigabit , 2 cổng quang - Tương thích chuẩn IEEE 802.3af/at. - Công suất tiêu thụ tối đa: 400W | D15: Cái | F15: 0.18
A16: =_xlfn.AGGREGATE(3,3,$B$9:B16) -> 8 | B16: Switch 16 port CISCO CBS110-16T-EU | C16: - Hỗ trợ 16 cổng Gigabit Ethernet RJ-45 - Công suất tiêu thụ tối đa: 9,96W | D16: Cái | F16: 0.18
B17: Switch 24 port CISCO CBS110-16T-EU | D17: Cái | F17: 0.18
A18: =_xlfn.AGGREGATE(3,3,$B$9:B18) -> 10 | B18: Màn hình quan sát 43 inch SamSung | C18: - Kích cỡ màn hình: 43 inch - Thương hiệu: Samsung - khung kệ + HDMI (15m) - Công suất tiêu thụ tối đa: 115W (Thông số tham khảo) | D18: Bộ | F18: 0.34
A19: 8.1 | B19: ='PTLL (2)'!B12 -> Màn hình quan sát SamSung 43inch | D19: =VLOOKUP(B19,'PTLL (2)'!$B$5:$J$42,2,0) -> Cái
A20: 8.2 | B20: ='PTLL (2)'!B13 -> Khung kệ tivi | D20: =VLOOKUP(B20,'PTLL (2)'!$B$5:$J$42,2,0) -> Cái
A21: 8.3 | B21: ='PTLL (2)'!B14 -> Cáp HDMI 15m Unitek | D21: =VLOOKUP(B21,'PTLL (2)'!$B$5:$J$42,2,0) -> Sợi
A22: II. HẠNG MỤC TRUYỀN DẪN
A23: 1 | B23: Cáp quang 4FO | C23: - Loại sợi quang: Singlemode - Số sợi quang: 4 - Đường kính cáp: 6 mm ±0,3 | D23: Mét | F23: 0.007
A24: 2 | B24: Cáp mạng Cat5E | C24: - Chuẩn cáp: Cat5e (ANSI/TIA-568.2-D) - Loại cáp: U/UTP – 4 Pair | D24: Mét | F24: 0.01 | G24: =F24*E24 -> 0 | H24: LS/Panduit/Comspose
A25: 3 | B25: Cáp mạng Cat5E | C25: - Chuẩn cáp: Cat6 (ANSI/TIA-568.2-D) - Loại cáp: U/UTP – 4 Pair | D25: Mét | F25: 0.01 | H25: LS/Panduit/Comspose
A26: 4 | B26: Bộ chuyển đổi quang điện Gigabit GNETCOM 10/100/1000M GNC-2111S-20A/B | C26: - Bộ chuyển đổi quang điện 10/100/1000M - Single Fiber/ Multi mode (1 Sợi quang) - Hỗ trợ bước sóng 1310nm/1550nm - Multi-Mode:2 km; Single-Mode:20km - One optical port: SC - Công suất tiêu thụ tối đa: <5W | D26: Bộ | F26: 0.018
A27: 5 | B27: Khay nguồn tập trung converter quang GNET HHD-G14M | C27: - Vỏ kim loại, Satndard 19 inch, chiều cao 2U - Hỗ trợ tối đa 14 cái 10/100M, 10/100/ 1000M Bộ chuyển đổi phương tiện độc lập - Nguồn điện AC 220V dự phòng - Công suất tiêu thụ tối đa: 40W (tham khảo) | D27: Bộ | F27: 0.18
A28: 6 | B28: Tủ mạng rack 2U | C28: - Tủ Rack treo tường, chuẩn rack 19 inch, Chiều cao 2U - Kích thước (WxHxD) 440x120x370 mm | D28: Bộ | F28: 0.765
A29: 7 | B29: Tủ mạng rack 6U | C29: - Tủ Rack treo tường, chuẩn rack 19 inch, Chiều cao 6U - Kích thước (WxHxD) 550x320x400 mm | D29: Bộ | F29: 0.765
A30: 8 | B30: Tủ mạng rack 10U( Có bánh xe) | C30: – Tủ Rack 10U D600 có bánh xe, màu Đen – Kích thước: H520xW550xD600mm | D30: Bộ | F30: 0.765
A31: 9 | B31: Tủ mạng rack 32U | D31: Bộ | F31: 2
B32: Tủ mạng rack 32U | D32: Bộ | F32: 2
A33: 10 | B33: ='PTLL (2)'!B21 -> Tủ mạng rack 42U | C33: - Kích thước: W600xH205xD1000 - Chuẩn rack 19 inch - Cửa trước là cửa cánh lưới, có khóa an toàn - Cửa sau là cửa cánh tôn, có khóa an toàn | D33: =VLOOKUP(B33,'PTLL (2)'!$B$5:$J$42,2,0) -> Cái | F33: 2
B34: ODF 12FO SC/UPC (Full Phụ kiện) | D34: Cái | F34: 1
A35: 11 | B35: ODF 24FO SC/UPC (Full Phụ kiện) | C35: - Hộp phối quang ODF Rack Mount dung lượng 24 cổng. - Trang bị đầy đủ adapter SC/UPC. - Kèm dây pigtail SC/UPC. - Chuẩn rack 1U, lắp đặt trong tủ rack 19 inch. | D35: Cái | F35: 1
A36: III. HẠNG MỤC ĐIỆN
A37: 1 | B37: ='PTLL (2)'!B24 -> Dây điện CVV 2x2.5 | C37: - Tiết diện danh định 2×2.5 mm2 - Cấp điện áp 300/500 - Chất liệu Ruột đồng, vỏ nhựa PVC | D37: =VLOOKUP(B37,'PTLL (2)'!$B$5:$J$42,2,0) -> Mét | F37: 0.01 | H37: =converter*20+30(FCC)
A38: 2 | B38: Thanh nguồn PDU đa năng 6 ổ cắm 3 chấu chuẩn 19" | C38: – Kích thước: 19″ – Số ổ: 06 ổ cắm 3 chấu – Công suất tối đa: 20A – Cáp nguồn: 2m (3×1.5mm2) | D38: =VLOOKUP(B38,'PTLL (2)'!$B$5:$J$42,2,0) -> Cái | F38: 0.04
A39: IV. HẠNG MỤC NGUỒN DỰ PHÒNG
A40: 1 | B40: Nguồn lưu điện UPS ARES Model AR610 1000VA/800W | C40: - Công suất: 1000VA/800W - Nguồn điện vào: 220V / 230V / 240V - Nguồn điện ra: 220V/230V/240VAC ± 5% - Tần số nguồn ra: 50/60Hz ± 0.3Hz - Ắc quy: 2x12V/7AH | D40: Bộ | F40: 0.245
A41: 2 | B41: Nguồn lưu điện UPS ARES Model AR630 3000VA-2400W | C41: - Công suất: 3000VA/2400W - Nguồn điện vào: 220V / 230V / 240V - Nguồn điện ra: 220V/230V/240VAC ± 5% - Tần số nguồn ra: 50/60Hz ± 0.3Hz - Ắc quy: 4x12V/9AH | D41: Bộ | F41: 0.245
A42: V. VẬT TƯ PHỤ
A43: 1 | B43: ='[14]ptll 61 cam'!B29 -> Vật tư phụ | C43: Bao gồm bọ, vít, tacke… | D43: =VLOOKUP(B43,'[14]ptll 61 cam'!$B$6:$K$35,4,0) -> Gói | H43: Dự kiến 1,500,000 VNĐ/10 Camera
...

Sheet tính cáp
B3: THÁP A
B4: Tủ | C4: Tầng camera | D4: Tầng đặt tủ | E4: Số camera | F4: Mét AutoCAD | G4: Thông tầng | H4: Xuống tủ | I4: Trong tủ | J4: Tổng cáp/tầng

Sheet PTLL (2)
A1: PHÂN TÍCH LÃI LỖ HỆ THỐNG 127 CAMERA SUNRISE LÔ E | S1: Giá trị phải phân bổ | T1: =C71 -> 73314880 | X1: ĐÃ PHÂN BỔ | Y1: =AC43-U43 -> #DIV/0!
A2: STT | B2: NỘI DUNG CÔNG VIỆC | C2: Đ.VỊ | D2: SLG | E2: GIÁ NHẬP | H2: GIÁ BÁN | M2: GIÁ NIÊM YẾT | N2: % GIẢM | O2: Giá bán ra | P2: % lãi | S2: Giá trị được chọn pb | T2: =SUMIF($AD$5:$AD$27,C72,$U$5:$U$27) -> 0 | U2: =T1/T2 -> #DIV/0! | X2: Giá trị còn lại phải pb | Y2: =T1-Y1 -> #DIV/0!
E3: G.Đơn vị | F3: Thành tiền | G3: VNĐ | H3: % | I3: G.Đơn vị | J3: Thành tiền | K3: Lợi nhuận | L3: GHI CHÚ | P3: giá bán/giá nhập | R3: SL | S3: Giá ncc | T3: Giá báo | U3: Thành tiền | V3: Giá sau PB LẦN 1 | W3: %tăng so với giá trị báo | X3: Giá sau PB LẦN 2 | Y3: %tăng so với giá trị báo | Z3: SL PB | AA3: SL CUỐI | AB3: ĐƠN GIÁ | AC3: THÀNH TIỀN | AD3: Mã Pb
A4: I | B4: HỆ THỐNG CAMERA | F4: =SUBTOTAL(9,F5:F14) -> 1.8495273e+08 | H4: =K4/F4 -> 0.26362559 | J4: =SUBTOTAL(9,J5:J14) -> 233711000 | K4: =SUBTOTAL(9,K5:K14) -> 48758273
A5: =_xlfn.AGGREGATE(3,5,$B$5:B5) -> 0 | B5: Camera IP Dome 2MP HIKVISION DS-2CD1121G0-I | C5: Cái | D5: 113 | E5: 500000 | F5: =E5*D5 -> 56500000 | H5: =P5-1 -> 0.3 | I5: =ROUNDUP((E5+G5+E5*H5),-3) -> 650000 | J5: =I5*D5 -> 73450000 | K5: =J5-F5 -> 16950000 | M5: =1300000/1.1 -> 1181818.2 | N5: 0.45 | O5: =M5*(1-N5) -> 650000 | P5: =O5/E5 -> 1.3 | Q5: =E5/M5 -> 0.42307692 | R5: =D5 -> 113 | S5: =E5 -> 500000 | T5: =I5 -> 650000 | U5: =T5*R5 -> 73450000 | V5: =IF(AD5=1,U5*$U$2/R5+T5,T5) -> #DIV/0! | W5: =1-T5/V5 -> #DIV/0! | X5: 940000 | Y5: =IF(X5<>0,1-T5/X5," ") -> 0.30851064 | AA5: =IF(Z5<>0,Z5,R5) -> 113 | AB5: =IF(X5<>0, X5,V5) -> 940000 | AC5: =AA5*AB5 -> 106220000 | AD5: 1
A6: =_xlfn.AGGREGATE(3,5,$B$5:B6) -> 0 | B6: Camera IP thân 2MP HIKVISION DS-2CD1021G0-I | C6: Cái | D6: 14 | E6: 500000 | F6: =E6*D6 -> 7000000 | H6: =P6-1 -> 0.26454545 | I6: =ROUNDUP((E6+G6+E6*H6),-3) -> 633000 | J6: =I6*D6 -> 8862000 | K6: =J6-F6 -> 1862000 | M6: =1300000/1.1 -> 1181818.2 | N6: 0.465 | O6: =M6*(1-N6) -> 632272.73 | P6: =O6/E6 -> 1.2645455
A7: =_xlfn.AGGREGATE(3,5,$B$5:B7) -> 0 | B7: Đầu ghi hình camera IP 32 kênh HIKVISION DS-7732NXI-K4 | C7: Cái | D7: 4 | E7: =7500000/1.1 -> 6818181.8 | F7: =E7*D7 -> 27272727 | H7: =P7-1 -> 0.26844 | I7: =ROUNDUP((E7+G7+E7*H7),-3) -> 8649000 | J7: =I7*D7 -> 34596000 | K7: =J7-F7 -> 7323272.7 | M7: =16690000/1.1 -> 15172727 | N7: 0.43 | O7: =M7*(1-N7) -> 8648454.5 | P7: =O7/E7 -> 1.26844 | R7: =D7 -> 4 | S7: =E7 -> 6818181.8 | T7: =I7 -> 8649000 | U7: =T7*R7 -> 34596000 | V7: =IF(AD7=1,U7*$U$2/R7+T7,T7) -> #DIV/0! | W7: =1-T7/V7 -> #DIV/0! | X7: 66800000 | Y7: =IF(X7<>0,1-T7/X7," ") -> 0.87052395 | AA7: =IF(Z7<>0,Z7,R7) -> 4 | AB7: =IF(X7<>0, X7,V7) -> 66800000 | AC7: =AA7*AB7 -> 267200000 | AD7: 1
A8: =_xlfn.AGGREGATE(3,5,$B$5:B8) -> 0 | B8: Ổ Cứng 8T WESTERN | C8: Cái | D8: 8 | E8: =5060000/1.1 -> 4600000 | F8: =E8*D8 -> 36800000 | H8: 0.163 | I8: =ROUNDUP((E8+G8+E8*H8),-3) -> 5350000 | J8: =I8*D8 -> 42800000 | K8: =J8-F8 -> 6000000 | M8: 5879000 | N8: 0.18 | O8: =M8*(1-N8) -> 4820780 | P8: =O8/E8 -> 1.0479957 | R8: =D8 -> 8 | S8: =E8 -> 4600000 | T8: =I8 -> 5350000 | U8: =T8*R8 -> 42800000 | V8: =IF(AD8=1,U8*$U$2/R8+T8,T8) -> 5350000 | W8: =1-T8/V8 -> 0 | Y8: =IF(X8<>0,1-T8/X8," ") | AA8: =IF(Z8<>0,Z8,R8) -> 8 | AB8: =IF(X8<>0, X8,V8) -> 5350000 | AC8: =AA8*AB8 -> 42800000
A9: =_xlfn.AGGREGATE(3,5,$B$5:B9) -> 0 | B9: Switch Hikvision POE 24 cổng DS-3E1326P-EI | C9: Cái | D9: 4 | E9: 3750000 | F9: =E9*D9 -> 15000000 | H9: =P9-1 -> 0.20632727 | I9: =ROUNDUP((E9+G9+E9*H9),-3) -> 4524000 | J9: =I9*D9 -> 18096000 | K9: =J9-F9 -> 3096000 | M9: =8730000/1.1 -> 7936363.6 | N9: 0.43 | O9: =M9*(1-N9) -> 4523727.3 | P9: =O9/E9 -> 1.2063273 | R9: =D9 -> 4 | S9: =E9 -> 3750000 | T9: =I9 -> 4524000 | U9: =T9*R9 -> 18096000 | V9: =IF(AD9=1,U9*$U$2/R9+T9,T9) -> #DIV/0! | W9: =1-T9/V9 -> #DIV/0! | X9: 8480000 | Y9: =IF(X9<>0,1-T9/X9," ") -> 0.46650943 | AA9: =IF(Z9<>0,Z9,R9) -> 4 | AB9: =IF(X9<>0, X9,V9) -> 8480000 | AC9: =AA9*AB9 -> 33920000 | AD9: 1
A10: =_xlfn.AGGREGATE(3,5,$B$5:B10) -> 0 | B10: Switch Hikvision POE 16 cổng DS-3E1318P-EI | C10: Cái | D10: 4 | E10: 3000000 | F10: =E10*D10 -> 12000000 | H10: =P10-1 -> 0.3205 | I10: =ROUNDUP((E10+G10+E10*H10),-3) -> 3962000 | J10: =I10*D10 -> 15848000 | K10: =J10-F10 -> 3848000 | M10: 6950000 | N10: 0.43 | O10: =M10*(1-N10) -> 3961500 | P10: =O10/E10 -> 1.3205 | R10: =D10 -> 4 | S10: =E10 -> 3000000 | T10: =I10 -> 3962000 | U10: =T10*R10 -> 15848000 | V10: =IF(AD10=1,U10*$U$2/R10+T10,T10) -> #DIV/0! | W10: =1-T10/V10 -> #DIV/0! | X10: 6150000 | Y10: =IF(X10<>0,1-T10/X10," ") -> 0.35577236 | AA10: =IF(Z10<>0,Z10,R10) -> 4 | AB10: =IF(X10<>0, X10,V10) -> 6150000 | AC10: =AA10*AB10 -> 24600000 | AD10: 1
A11: =_xlfn.AGGREGATE(3,5,$B$5:B11) -> 0 | B11: Switch 16 port CISCO CBS110-16T-EU | C11: Cái | D11: 1 | E11: 2780000 | F11: =E11*D11 -> 2780000 | H11: 0.25 | I11: =ROUNDUP((E11+G11+E11*H11),-3) -> 3475000 | J11: =I11*D11 -> 3475000 | K11: =J11-F11 -> 695000 | M11: 1499000 | N11: 0.05 | O11: =M11*(1-N11) -> 1424050 | P11: =O11/E11 -> 0.5122482 | R11: =D11 -> 1 | S11: =E11 -> 2780000 | T11: =I11 -> 3475000 | U11: =T11*R11 -> 3475000 | V11: =IF(AD11=1,U11*$U$2/R11+T11,T11) -> #DIV/0! | W11: =1-T11/V11 -> #DIV/0! | X11: 2150000 | Y11: =IF(X11<>0,1-T11/X11," ") -> -0.61627907 | AA11: =IF(Z11<>0,Z11,R11) -> 1 | AB11: =IF(X11<>0, X11,V11) -> 2150000 | AC11: =AA11*AB11 -> 2150000 | AD11: 1
A12: =_xlfn.AGGREGATE(3,5,$B$5:B12) -> 0 | B12: Màn hình quan sát SamSung 43inch | C12: Cái | D12: 4 | E12: 6200000 | F12: =E12*D12 -> 24800000 | H12: 0.29 | I12: =ROUNDUP((E12+G12+E12*H12),-3) -> 7998000 | J12: =I12*D12 -> 31992000 | K12: =J12-F12 -> 7192000 | R12: =D12 -> 4 | S12: =E12 -> 6200000 | T12: =I12 -> 7998000 | U12: =T12*R12 -> 31992000 | V12: =IF(AD12=1,U12*$U$2/R12+T12,T12) -> #DIV/0! | W12: =1-T12/V12 -> #DIV/0! | X12: 500000 | Y12: =IF(X12<>0,1-T12/X12," ") -> -14.996 | AA12: =IF(Z12<>0,Z12,R12) -> 4 | AB12: =IF(X12<>0, X12,V12) -> 500000 | AC12: =AA12*AB12 -> 2000000 | AD12: 1
A13: =_xlfn.AGGREGATE(3,5,$B$5:B13) -> 0 | B13: =[15]BOq!B26 -> Khung kệ tivi | C13: Cái | D13: 4 | E13: 300000 | F13: =E13*D13 -> 1200000 | H13: 0.66 | I13: =ROUNDUP((E13+G13+E13*H13),-3) -> 498000 | J13: =I13*D13 -> 1992000 | K13: =J13-F13 -> 792000 | P13: =O13/E13 -> 0 | R13: =D13 -> 4 | S13: =E13 -> 300000 | T13: =I13 -> 498000 | U13: =T13*R13 -> 1992000 | V13: =IF(AD13=1,U13*$U$2/R13+T13,T13) -> #DIV/0! | W13: =1-T13/V13 -> #DIV/0! | Y13: =IF(X13<>0,1-T13/X13," ") | Z13: 600 | AA13: =IF(Z13<>0,Z13,R13) -> 600 | AB13: =IF(X13<>0, X13,V13) -> #DIV/0! | AC13: =AA13*AB13 -> #DIV/0! | AD13: 1
A14: =_xlfn.AGGREGATE(3,5,$B$5:B14) -> 0 | B14: =[15]BOq!B27 -> Cáp HDMI 15m Unitek | C14: Sợi | D14: 4 | E14: 400000 | F14: =E14*D14 -> 1600000 | H14: 0.625 | I14: =ROUNDUP((E14+G14+E14*H14),-3) -> 650000 | J14: =I14*D14 -> 2600000 | K14: =J14-F14 -> 1000000 | M14: =3475000/305 -> 11393.443 | N14: 0.1 | O14: =M14*(1-N14) -> 10254.098 | P14: =O14/E14 -> 0.025635246 | R14: =D14 -> 4 | S14: =E14 -> 400000 | T14: =I14 -> 650000 | U14: =T14*R14 -> 2600000 | V14: =IF(AD14=1,U14*$U$2/R14+T14,T14) -> 650000 | W14: =1-T14/V14 -> 0 | Y14: =IF(X14<>0,1-T14/X14," ") | Z14: 3200 | AA14: =IF(Z14<>0,Z14,R14) -> 3200 | AB14: =IF(X14<>0, X14,V14) -> 650000 | AC14: =AA14*AB14 -> 2080000000
A15: II | B15: HẠNG MỤC TRUYỀN DẪN | F15: =SUBTOTAL(9,F16:F22) -> 48256885 | H15: =K15/F15 -> 0.78453291 | J15: =SUBTOTAL(9,J16:J22) -> 86116000 | K15: =SUBTOTAL(9,K16:K22) -> 37859115
A16: 1 | B16: Cáp quang 4FO | C16: Mét | D16: 400 | E16: 2300 | F16: =E16*D16 -> 920000 | H16: 1.4 | I16: =ROUNDUP((E16+G16+E16*H16),-2) -> 5600 | J16: =I16*D16 -> 2240000 | K16: =J16-F16 -> 1320000 | P16: =O16/E16 -> 0 | R16: =D16 -> 400 | S16: =E16 -> 2300 | T16: =I16 -> 5600 | U16: =T16*R16 -> 2240000 | V16: =IF(AD16=1,U16*$U$2/R16+T16,T16) -> #DIV/0! | W16: =1-T16/V16 -> #DIV/0! | X16: 34000 | Y16: =IF(X16<>0,1-T16/X16," ") -> 0.83529412 | AA16: =IF(Z16<>0,Z16,R16) -> 400 | AB16: =IF(X16<>0, X16,V16) -> 34000 | AC16: =AA16*AB16 -> 13600000 | AD16: 1
A17: 2 | B17: Cáp mạng Cat5E | C17: Mét | D17: 7300 | E17: 4655.7377 | F17: =E17*D17 -> 33986885 | H17: 0.92 | I17: =ROUNDUP((E17+G17+E17*H17),-2) -> 9000 | J17: =I17*D17 -> 65700000 | K17: =J17-F17 -> 31713115 | R17: =D17 -> 7300 | S17: =E17 -> 4655.7377 | T17: =I17 -> 9000 | U17: =T17*R17 -> 65700000 | V17: =IF(AD17=1,U17*$U$2/R17+T17,T17) -> 9000 | W17: =1-T17/V17 -> 0 | X17: 1050000 | Y17: =IF(X17<>0,1-T17/X17," ") -> 0.99142857 | AA17: =IF(Z17<>0,Z17,R17) -> 7300 | AB17: =IF(X17<>0, X17,V17) -> 1050000 | AC17: =AA17*AB17 -> 7665000000
A18: 3 | B18: Converter A/B 1000M | C18: Bộ | D18: 4 | E18: 600000 | F18: =E18*D18 -> 2400000 | H18: 0.8 | I18: =ROUNDUP((E18+G18+E18*H18),-3) -> 1080000 | J18: =I18*D18 -> 4320000 | K18: =J18-F18 -> 1920000 | O18: =M18*(1-N18) -> 0 | P18: =O18/E18 -> 0 | R18: =D18 -> 4 | S18: =E18 -> 600000 | T18: =I18 -> 1080000 | U18: =T18*R18 -> 4320000 | V18: =IF(AD18=1,U18*$U$2/R18+T18,T18) -> #DIV/0! | W18: =1-T18/V18 -> #DIV/0! | Y18: =IF(X18<>0,1-T18/X18," ") | AA18: =IF(Z18<>0,Z18,R18) -> 4 | AB18: =IF(X18<>0, X18,V18) -> #DIV/0! | AC18: =AA18*AB18 -> #DIV/0! | AD18: 1
A19: 4 | B19: Tủ mạng rack 6U | C19: Cái | D19: 2 | E19: 700000 | F19: =E19*D19 -> 1400000 | H19: 0.45 | I19: =ROUNDUP((E19+G19+E19*H19),-3) -> 1015000 | J19: =I19*D19 -> 2030000 | K19: =J19-F19 -> 630000 | M19: 2300000 | N19: 0.25 | O19: =M19*(1-N19) -> 1725000 | P19: =O19/E19 -> 2.4642857 | R19: =D19 -> 2 | S19: =E19 -> 700000 | T19: =I19 -> 1015000 | U19: =T19*R19 -> 2030000 | V19: =IF(AD19=1,U19*$U$2/R19+T19,T19) -> #DIV/0! | W19: =1-T19/V19 -> #DIV/0! | X19: 2590000 | Y19: =IF(X19<>0,1-T19/X19," ") -> 0.60810811 | AA19: =IF(Z19<>0,Z19,R19) -> 2 | AB19: =IF(X19<>0, X19,V19) -> 2590000 | AC19: =AA19*AB19 -> 5180000 | AD19: 1
A20: 5 | B20: Tủ mạng rack 10U | C20: Cái | D20: 2 | E20: 1400000 | F20: =E20*D20 -> 2800000 | H20: 0.17 | I20: =ROUNDUP((E20+G20+E20*H20),-3) -> 1638000 | J20: =I20*D20 -> 3276000 | K20: =J20-F20 -> 476000 | M20: 2300000 | N20: 0.25 | O20: =M20*(1-N20) -> 1725000 | P20: =O20/E20 -> 1.2321429 | R20: =D20 -> 2 | S20: =E20 -> 1400000 | T20: =I20 -> 1638000 | U20: =T20*R20 -> 3276000 | V20: =IF(AD20=1,U20*$U$2/R20+T20,T20) -> #DIV/0! | W20: =1-T20/V20 -> #DIV/0! | X20: 2590000 | Y20: =IF(X20<>0,1-T20/X20," ") -> 0.36756757 | AA20: =IF(Z20<>0,Z20,R20) -> 2 | AB20: =IF(X20<>0, X20,V20) -> 2590000 | AC20: =AA20*AB20 -> 5180000 | AD20: 1
A21: 6 | B21: Tủ mạng rack 42U | C21: Cái | D21: 1 | E21: 6300000 | F21: =E21*D21 -> 6300000 | H21: 0.25 | I21: =ROUNDUP((E21+G21+E21*H21),-3) -> 7875000 | J21: =I21*D21 -> 7875000 | K21: =J21-F21 -> 1575000 | M21: =I21/32 -> 246093.75 | R21: =D21 -> 1 | S21: =E21 -> 6300000 | AA21: =IF(Z21<>0,Z21,R21) -> 1
A22: 7 | B22: ODF 12 FO | C22: Cái | D22: 1 | E22: 450000 | F22: =E22*D22 -> 450000 | H22: 0.5 | I22: =ROUNDUP((E22+G22+E22*H22),-3) -> 675000 | J22: =I22*D22 -> 675000 | K22: =J22-F22 -> 225000 | R22: =D22 -> 1 | AA22: =IF(Z22<>0,Z22,R22) -> 1
A23: III . | B23: HẠNG MỤC ĐIỆN | F23: =SUBTOTAL(9,F24:F25) -> 5760000 | H23: =K23/SUM(F23:F23) -> 0.10416667 | J23: =SUBTOTAL(9,J24:J25) -> 6360000 | K23: =SUBTOTAL(9,K24:K25) -> 600000
A24: 1 | B24: Dây điện CVV 2x2.5 | C24: Mét | D24: 150 | E24: 20000 | F24: =E24*D24 -> 3000000 | H24: 0.09 | I24: =ROUNDUP((E24+G24+E24*H24),-2) -> 21800 | J24: =I24*D24 -> 3270000 | K24: =J24-F24 -> 270000 | M24: =2800/305 -> 9.1803279 | R24: =D24 -> 150 | S24: =E24 -> 20000 | T24: =I24 -> 21800 | U24: =T24*R24 -> 3270000 | V24: =IF(AD24=1,U24*$U$2/R24+T24,T24) -> #DIV/0! | W24: =1-T24/V24 -> #DIV/0! | X24: 5000 | Y24: =IF(X24<>0,1-T24/X24," ") -> -3.36 | Z24: 1350 | AA24: =IF(Z24<>0,Z24,R24) -> 1350 | AB24: =IF(X24<>0, X24,V24) -> 5000 | AC24: =AA24*AB24 -> 6750000 | AD24: 1
A25: 2 | B25: Thanh nguồn PDU đa năng 6 ổ cắm 3 chấu chuẩn 19" | C25: Cái | D25: 3 | E25: 920000 | F25: =E25*D25 -> 2760000 | H25: 0.119 | I25: =ROUNDUP((E25+G25+E25*H25),-3) -> 1030000 | J25: =I25*D25 -> 3090000 | K25: =J25-F25 -> 330000 | R25: =D25 -> 3 | S25: =E25 -> 920000 | T25: =I25 -> 1030000 | U25: =T25*R25 -> 3090000 | V25: =IF(AD25=1,U25*$U$2/R25+T25,T25) -> 1030000 | W25: =1-T25/V25 -> 0 | Y25: =IF(X25<>0,1-T25/X25," ") | AA25: =IF(Z25<>0,Z25,R25) -> 3 | AB25: =IF(X25<>0, X25,V25) -> 1030000 | AC25: =AA25*AB25 -> 3090000
A26: IV . | B26: HẠNG MỤC ĐIỆN DỰ PHÒNG | F26: =SUBTOTAL(9,F27:F29) -> 21826364 | H26: =K26/SUM(F26:F26) -> 0.25009371 | J26: =SUBTOTAL(9,J27:J29) -> 27285000 | K26: =SUBTOTAL(9,K27:K29) -> 5458636.4 | N26: =#REF!+#REF! -> #REF! | R26: =D26 -> 0 | U26: =T26*R26 -> 0 | V26: =IF(AD26=1,U26*$U$2/R26+T26,T26) -> 0 | Y26: =IF(X26<>0,1-T26/X26," ") | AA26: =IF(Z26<>0,Z26,R26) -> 0 | AB26: =IF(X26<>0, X26,V26) -> 0 | AC26: =AA26*AB26 -> 0
A27: 1 | B27: Nguồn lưu điện 2KVA UPS | C27: Bộ | D27: 2 | E27: =5700000/1.1 -> 5181818.2 | F27: =E27*D27 -> 10363636 | H27: 0.25 | I27: =ROUNDUP((E27+G27+E27*H27),-3) -> 6478000 | J27: =I27*D27 -> 12956000 | K27: =J27-F27 -> 2592363.6 | R27: =D27 -> 2 | S27: =E27 -> 5181818.2 | T27: =I27 -> 6478000 | U27: =T27*R27 -> 12956000 | V27: =IF(AD27=1,U27*$U$2/R27+T27,T27) -> #DIV/0! | W27: =1-T27/V27 -> #DIV/0! | X27: 7120000 | Y27: =IF(X27<>0,1-T27/X27," ") -> 0.090168539 | AA27: =IF(Z27<>0,Z27,R27) -> 2 | AB27: =IF(X27<>0, X27,V27) -> 7120000 | AC27: =AA27*AB27 -> 14240000 | AD27: 1
A28: 2 | B28: Nguồn lưu điện 1K2VA UPS | C28: Bộ | D28: 2 | E28: =2382000/1.1 -> 2165454.5 | F28: =E28*D28 -> 4330909.1 | H28: 0.25 | I28: =ROUNDUP((E28+G28+E28*H28),-3) -> 2707000 | J28: =I28*D28 -> 5414000 | K28: =J28-F28 -> 1083090.9 | R28: =D28 -> 2 | AA28: =IF(Z28<>0,Z28,R28) -> 2
A29: 3 | B29: Nguồn lưu điện 3KVA UPS | C29: Bộ | D29: 1 | E29: =7845000/1.1 -> 7131818.2 | F29: =E29*D29 -> 7131818.2 | H29: 0.25 | I29: =ROUNDUP((E29+G29+E29*H29),-3) -> 8915000 | J29: =I29*D29 -> 8915000 | K29: =J29-F29 -> 1783181.8 | R29: =D29 -> 1 | AA29: =IF(Z29<>0,Z29,R29) -> 1
A30: IV. VẬT TƯ PHỤ | F30: =SUBTOTAL(9,F31:F35) -> 22472000 | H30: =K30/SUM(F30:F30) -> 0.46386614 | J30: =SUBTOTAL(9,J31:J35) -> 32896000 | K30: =SUBTOTAL(9,K31:K35) -> 10424000
A31: 1 | B31: Vật tư phụ | C31: Gói | D31: 1 | E31: 15000000 | F31: =E31*D31 -> 15000000 | H31: 0.4 | I31: =ROUNDUP((E31+G31+E31*H31),-3) -> 21000000 | J31: =I31*D31 -> 21000000 | K31: =J31-F31 -> 6000000 | R31: =D31 -> 1 | S31: =E31 -> 15000000 | T31: =I31 -> 21000000 | U31: =T31*R31 -> 21000000 | V31: =IF(AD31=1,U31*$U$2/R31+T31,T31) -> #DIV/0! | W31: =1-T31/V31 -> #DIV/0! | X31: 19500 | Y31: =IF(X31<>0,1-T31/X31," ") -> -1075.9231 | AA31: =IF(Z31<>0,Z31,R31) -> 1 | AB31: =IF(X31<>0, X31,V31) -> 19500 | AC31: =AA31*AB31 -> 19500 | AD31: 1
A32: 2 | B32: Dây nhảy quang SC-UPC/SC-UPC (3 Mét) | C32: Sợi | D32: 8 | E32: 19000 | F32: =E32*D32 -> 152000 | H32: 0.4 | I32: =ROUNDUP((E32+G32+E32*H32),-3) -> 27000 | J32: =I32*D32 -> 216000 | K32: =J32-F32 -> 64000 | P32: =O32/E32 -> 0 | R32: =D32 -> 8 | S32: =E32 -> 19000 | T32: =I32 -> 27000 | U32: =T32*R32 -> 216000 | V32: =IF(AD32=1,U32*$U$2/R32+T32,T32) -> #DIV/0! | W32: =1-T32/V32 -> #DIV/0! | X32: 160000 | Y32: =IF(X32<>0,1-T32/X32," ") -> 0.83125 | AA32: =IF(Z32<>0,Z32,R32) -> 8 | AB32: =IF(X32<>0, X32,V32) -> 160000 | AC32: =AA32*AB32 -> 1280000 | AD32: 1
A33: 3 | B33: Ruột gà phi 20 | C33: Mét | D33: 1700 | E33: =150000/50 -> 3000 | F33: =E33*D33 -> 5100000 | H33: 0.35 | I33: =ROUNDUP((E33+G33+E33*H33),-3) -> 5000 | J33: =I33*D33 -> 8500000 | K33: =J33-F33 -> 3400000 | R33: =D33 -> 1700 | S33: =E33 -> 3000 | T33: =I33 -> 5000 | U33: =T33*R33 -> 8500000 | V33: =IF(AD33=1,U33*$U$2/R33+T33,T33) -> #DIV/0! | W33: =1-T33/V33 -> #DIV/0! | Y33: =IF(X33<>0,1-T33/X33," ") | AA33: =IF(Z33<>0,Z33,R33) -> 1700 | AB33: =IF(X33<>0, X33,V33) -> #DIV/0! | AC33: =AA33*AB33 -> #DIV/0! | AD33: 1
A34: 4 | B34: ODF 2FO | C34: Cái | D34: 4 | E34: 30000 | F34: =E34*D34 -> 120000 | H34: 0.5 | I34: =ROUNDUP((E34+G34+E34*H34),-3) -> 45000 | J34: =I34*D34 -> 180000 | K34: =J34-F34 -> 60000 | M34: https://dienmayhoanghai.vn/tivi-samsung/smart-tivi-samsung-4k-50-inch-50au7002-uhd-moi-2022.html | R34: =D34 -> 4 | S34: =E34 -> 30000 | T34: =I34 -> 45000 | U34: =T34*R34 -> 180000 | V34: =IF(AD34=1,U34*$U$2/R34+T34,T34) -> 45000 | W34: =1-T34/V34 -> 0 | Y34: =IF(X34<>0,1-T34/X34," ") | AA34: =IF(Z34<>0,Z34,R34) -> 4 | AB34: =IF(X34<>0, X34,V34) -> 45000 | AC34: =AA34*AB34 -> 180000
A35: 5 | B35: Ống điện phi 20 | C35: Mét | D35: 300 | E35: 7000 | F35: =E35*D35 -> 2100000 | H35: 0.36 | I35: =ROUNDUP((E35+G35+E35*H35),-3) -> 10000 | J35: =I35*D35 -> 3000000 | K35: =J35-F35 -> 900000
A36: V. | B36: NHÂN CÔNG | C36: Công | D36: =SUM(D37:D40) -> 160 | E36: =F36/D36 -> 458531.25 | F36: =SUBTOTAL(9,F37:F42) -> 73365000 | H36: 0.36 | I36: =ROUNDUP((E36+G36+E36*H36),-3) -> 624000 | J36: =I36*D36 -> 99840000 | K36: =J36-F36 -> 26475000 | M36: =56/61 -> 0.91803279 | U36: =T36*R36 -> 0 | Y36: =IF(X36<>0,1-T36/X36," ") | AA36: =IF(Z36<>0,Z36,R36) -> 0 | AB36: =IF(X36<>0, X36,V36) -> 0 | AC36: =AA36*AB36 -> 0
A37: 1 | B37: Nhân công thi công | C37: Công | D37: 117 | E37: 400000 | F37: =E37*D37 -> 46800000
A38: 2 | B38: Nhân công giám sát | C38: Công | D38: 39 | E38: 500000 | F38: =E38*D38 -> 19500000
A39: 3 | B39: Công thiết kế, khảo sát | C39: Công | D39: 2 | E39: 450000 | F39: =E39*D39 -> 900000
A40: 4 | B40: Công báo giá, hồ sơ thầu | C40: Công | D40: 2 | E40: 450000 | F40: =E40*D40 -> 900000
...
